Workbook

Sheet Quotations
A1: Date | B1: UBEUECR | C1: Date | D1: CSLOGBB | E1: Date | F1: CBSWBOB | G1: Date | H1: BNOPLPT | I1: Date | J1: ETHAKTE | K1: Date | L1: MPCGLCA | O1: =B1 -> UBEUECR | P1: =D1 -> CSLOGBB | Q1: =F1 -> CBSWBOB | R1: =H1 -> BNOPLPT | S1: =J1 -> ETHAKTE | T1: =L1 -> MPCGLCA
A2: 43465 | B2: 107.74 | C2: 43363 | D2: 23.93 | E2: 43465 | F2: 115.65 | G2: 43462 | H2: 109.46 | I2: 43462 | J2: 120.54 | K2: 43465 | L2: 1327.918 | N2: Weights | O2: 0.1666 | P2: 0.1666 | Q2: 0.1666 | R2: 0.1666 | S2: 0.1666 | T2: 0.1667
A3: 43462 | B3: 107.71 | C3: 43362 | D3: 23.94 | E3: 43462 | F3: 115.62 | G3: 43461 | H3: 109.34 | I3: 43461 | J3: 120.29 | K3: 43462 | L3: 1326.26
A4: 43461 | B4: 107.38 | C4: 43361 | D4: 23.94 | E4: 43461 | F4: 115.61 | G4: 43455 | H4: 109.29 | I4: 43455 | J4: 120.4 | K4: 43461 | L4: 1326.244
A5: 43455 | B5: 107.84 | C5: 43360 | D5: 23.94 | E5: 43455 | F5: 115.61 | G5: 43454 | H5: 109.29 | I5: 43454 | J5: 120.69 | K5: 43455 | L5: 1322.597
A6: 43454 | B6: 107.87 | C6: 43357 | D6: 23.93 | E6: 43454 | F6: 115.62 | G6: 43453 | H6: 109.14 | I6: 43453 | J6: 120.55 | K6: 43454 | L6: 1337.783
A7: 43453 | B7: 108.29 | C7: 43356 | D7: 23.93 | E7: 43453 | F7: 115.67 | G7: 43452 | H7: 109 | I7: 43452 | J7: 120.63 | K7: 43453 | L7: 1343.3
A8: 43452 | B8: 108.28 | C8: 43355 | D8: 23.94 | E8: 43452 | F8: 115.68 | G8: 43451 | H8: 108.91 | I8: 43451 | J8: 120.96 | K8: 43452 | L8: 1345.449
A9: 43451 | B9: 108.38 | C9: 43354 | D9: 23.94 | E9: 43451 | F9: 115.69 | G9: 43448 | H9: 108.92 | I9: 43448 | J9: 121.11 | K9: 43451 | L9: 1354.865
A10: 43448 | B10: 108.73 | C10: 43353 | D10: 23.94 | E10: 43448 | F10: 115.68 | G10: 43447 | H10: 108.95 | I10: 43447 | J10: 120.89 | K10: 43448 | L10: 1357.79
A11: 43447 | B11: 108.93 | C11: 43350 | D11: 23.94 | E11: 43447 | F11: 115.68 | G11: 43446 | H11: 108.81 | I11: 43446 | J11: 120.9 | K11: 43447 | L11: 1361.06
A12: 43446 | B12: 109.04 | C12: 43349 | D12: 23.94 | E12: 43446 | F12: 115.65 | G12: 43445 | H12: 108.5 | I12: 43445 | J12: 120.82 | K12: 43446 | L12: 1354.648
A13: 43445 | B13: 108.69 | C13: 43348 | D13: 23.93 | E13: 43445 | F13: 115.64 | G13: 43444 | H13: 108.91 | I13: 43444 | J13: 121.08 | K13: 43445 | L13: 1352.079
A14: 43444 | B14: 108.43 | C14: 43347 | D14: 23.95 | E14: 43444 | F14: 115.63 | G14: 43441 | H14: 108.73 | I14: 43441 | J14: 121.35 | K14: 43444 | L14: 1356.752
... A1188: 41719 | B1188: 122.41 | C1188: 41639 | D1188: 24 | E1188: 41736 | F1188: 112.65 | G1188: 41731 | H1188: 119.13 | I1188: 41731 | J1188: 125.04 | K1188: 41719 | L1188: 1351.2667
A1189: 41718 | B1189: 122.32 | E1189: 41733 | F1189: 112.67 | G1189: 41730 | H1189: 119.16 | I1189: 41730 | J1189: 125.17 | K1189: 41718 | L1189: 1351.1322
A1190: 41717 | B1190: 122.48 | E1190: 41732 | F1190: 112.62 | G1190: 41729 | H1190: 119.32 | I1190: 41729 | J1190: 125.07 | K1190: 41717 | L1190: 1353.1835
A1191: 41716 | B1191: 122.26 | E1191: 41731 | F1191: 112.57 | G1191: 41726 | H1191: 119.25 | I1191: 41726 | J1191: 124.95 | K1191: 41716 | L1191: 1346.7214
A1192: 41715 | B1192: 121.85 | E1192: 41730 | F1192: 112.5 | G1192: 41725 | H1192: 119.09 | I1192: 41725 | J1192: 124.82 | K1192: 41715 | L1192: 1339.6116
A1193: 41712 | B1193: 121.28 | E1193: 41729 | F1193: 112.44 | G1193: 41724 | H1193: 118.72 | I1193: 41724 | J1193: 124.85 | K1193: 41712 | L1193: 1342.7042
A1194: 41711 | B1194: 121.64 | E1194: 41726 | F1194: 112.39 | G1194: 41723 | H1194: 118.28 | I1194: 41723 | J1194: 124.74 | K1194: 41711 | L1194: 1351.4203
A1195: 41710 | B1195: 121.99 | E1195: 41725 | F1195: 112.34 | G1195: 41722 | H1195: 118.53 | I1195: 41722 | J1195: 124.74 | K1195: 41710 | L1195: 1354.0624
A1196: 41709 | B1196: 122.45 | E1196: 41724 | F1196: 112.32 | G1196: 41719 | H1196: 118.37 | I1196: 41719 | J1196: 124.71 | K1196: 41709 | L1196: 1356.5109
A1197: 41708 | B1197: 122.43 | E1197: 41723 | F1197: 112.25 | G1197: 41718 | H1197: 118.63 | I1197: 41718 | J1197: 124.81 | K1197: 41708 | L1197: 1360.7041
A1198: 41705 | B1198: 122.54 | E1198: 41722 | F1198: 112.21 | G1198: 41717 | H1198: 118.75 | I1198: 41717 | J1198: 124.91 | K1198: 41705 | L1198: 1364.042
A1199: 41704 | B1199: 122.74 | E1199: 41719 | F1199: 112.17 | G1199: 41716 | H1199: 118.78 | I1199: 41716 | J1199: 124.76 | K1199: 41704 | L1199: 1361.6333
A1200: 41703 | B1200: 122.57 | E1200: 41718 | F1200: 112.13 | G1200: 41715 | H1200: 118.89 | I1200: 41715 | J1200: 124.72 | K1200: 41703 | L1200: 1359.6813
... A1245: 41639 | B1245: 119.49 | E1245: 41655 | F1245: 111.9 | G1245: 41652 | H1245: 123.09 | I1245: 41652 | J1245: 123.99 | K1245: 41639 | L1245: 1317.5613
E1246: 41654 | F1246: 111.89 | G1246: 41649 | H1246: 123.16 | I1246: 41649 | J1246: 123.88
E1247: 41653 | F1247: 111.86 | G1247: 41648 | H1247: 123.35 | I1247: 41648 | J1247: 123.96
E1248: 41652 | F1248: 111.84 | G1248: 41647 | H1248: 123.26 | I1248: 41647 | J1248: 123.98
E1249: 41649 | F1249: 111.82 | G1249: 41646 | H1249: 123.28 | I1249: 41646 | J1249: 123.59
E1250: 41648 | F1250: 111.83 | G1250: 41645 | H1250: 123.32 | I1250: 41645 | J1250: 123.64
E1251: 41647 | F1251: 111.82 | G1251: 41642 | H1251: 123.32 | I1251: 41642 | J1251: 123.47
E1252: 41646 | F1252: 111.78 | G1252: 41641 | H1252: 123.23 | I1252: 41641 | J1252: 123.86
E1253: 41645 | F1253: 111.76
E1254: 41642 | F1254: 111.75
E1255: 41641 | F1255: 111.72
E1256: 41639 | F1256: 111.71

Sheet Q2
A1: Date | B1: UBEUECR | C1: CSLOGBB | D1: CBSWBOB | E1: BNOPLPT | F1: ETHAKTE | G1: MPCGLCA
A2: {=UNIQUE( SORT({ Quotations!A2:A1756; Quotations!C2:C1756; Quotations!E2:E1756; Quotations!G2:G1756; Quotations!I2:I1756; Quotations!K2:K1756 }) )} -> 41639 | B2: {=XLOOKUP($A2, Quotations!$A$2:A1756, Quotations!$B$2:B1756, "")} -> 119.49 | C2: {=XLOOKUP($A2, Quotations!$C$2:C1756, Quotations!$D$2:D1756, "")} -> 24 | D2: {=XLOOKUP($A2, Quotations!$E$2:E1756, Quotations!$F$2:F1756, "")} -> 111.71 | E2: {=XLOOKUP($A2, Quotations!$G$2:G1756, Quotations!$H$2:H1756, "")} | F2: {=XLOOKUP($A2, Quotations!$I$2:I1756, Quotations!$J$2:J1756, "")} | G2: {=XLOOKUP($A2, Quotations!$K$2:K1756, Quotations!$L$2:L1756, "")} -> 1317.5613
A3: 41641 | B3: {=XLOOKUP($A3, Quotations!$A$2:A1756, Quotations!$B$2:B1756, "")} -> 119.04 | C3: {=XLOOKUP($A3, Quotations!$C$2:C1756, Quotations!$D$2:D1756, "")} -> 24.02 | D3: {=XLOOKUP($A3, Quotations!$E$2:E1756, Quotations!$F$2:F1756, "")} -> 111.72 | E3: {=XLOOKUP($A3, Quotations!$G$2:G1756, Quotations!$H$2:H1756, "")} -> 123.23 | F3: {=XLOOKUP($A3, Quotations!$I$2:I1756, Quotations!$J$2:J1756, "")} -> 123.86 | G3: {=XLOOKUP($A3, Quotations!$K$2:K1756, Quotations!$L$2:L1756, "")} -> 1320.0796
A4: 41642 | B4: {=XLOOKUP($A4, Quotations!$A$2:A1756, Quotations!$B$2:B1756, "")} -> 119.26 | C4: {=XLOOKUP($A4, Quotations!$C$2:C1756, Quotations!$D$2:D1756, "")} -> 24.04 | D4: {=XLOOKUP($A4, Quotations!$E$2:E1756, Quotations!$F$2:F1756, "")} -> 111.75 | E4: {=XLOOKUP($A4, Quotations!$G$2:G1756, Quotations!$H$2:H1756, "")} -> 123.32 | F4: {=XLOOKUP($A4, Quotations!$I$2:I1756, Quotations!$J$2:J1756, "")} -> 123.47 | G4: {=XLOOKUP($A4, Quotations!$K$2:K1756, Quotations!$L$2:L1756, "")} -> 1316.1038
A5: 41645 | B5: {=XLOOKUP($A5, Quotations!$A$2:A1756, Quotations!$B$2:B1756, "")} -> 119.31 | C5: {=XLOOKUP($A5, Quotations!$C$2:C1756, Quotations!$D$2:D1756, "")} -> 24.03 | D5: {=XLOOKUP($A5, Quotations!$E$2:E1756, Quotations!$F$2:F1756, "")} -> 111.76 | E5: {=XLOOKUP($A5, Quotations!$G$2:G1756, Quotations!$H$2:H1756, "")} -> 123.32 | F5: {=XLOOKUP($A5, Quotations!$I$2:I1756, Quotations!$J$2:J1756, "")} -> 123.64 | G5: {=XLOOKUP($A5, Quotations!$K$2:K1756, Quotations!$L$2:L1756, "")} -> 1315.5184
A6: 41646 | B6: {=XLOOKUP($A6, Quotations!$A$2:A1756, Quotations!$B$2:B1756, "")} -> 119.73 | C6: {=XLOOKUP($A6, Quotations!$C$2:C1756, Quotations!$D$2:D1756, "")} -> 24.04 | D6: {=XLOOKUP($A6, Quotations!$E$2:E1756, Quotations!$F$2:F1756, "")} -> 111.78 | E6: {=XLOOKUP($A6, Quotations!$G$2:G1756, Quotations!$H$2:H1756, "")} -> 123.28 | F6: {=XLOOKUP($A6, Quotations!$I$2:I1756, Quotations!$J$2:J1756, "")} -> 123.59 | G6: {=XLOOKUP($A6, Quotations!$K$2:K1756, Quotations!$L$2:L1756, "")} -> 1314.9367
A7: 41647 | B7: {=XLOOKUP($A7, Quotations!$A$2:A1756, Quotations!$B$2:B1756, "")} -> 119.88 | C7: {=XLOOKUP($A7, Quotations!$C$2:C1756, Quotations!$D$2:D1756, "")} -> 24.04 | D7: {=XLOOKUP($A7, Quotations!$E$2:E1756, Quotations!$F$2:F1756, "")} -> 111.82 | E7: {=XLOOKUP($A7, Quotations!$G$2:G1756, Quotations!$H$2:H1756, "")} -> 123.26 | F7: {=XLOOKUP($A7, Quotations!$I$2:I1756, Quotations!$J$2:J1756, "")} -> 123.98 | G7: {=XLOOKUP($A7, Quotations!$K$2:K1756, Quotations!$L$2:L1756, "")} -> 1322.2889
A8: 41648 | B8: {=XLOOKUP($A8, Quotations!$A$2:A1756, Quotations!$B$2:B1756, "")} -> 119.81 | C8: {=XLOOKUP($A8, Quotations!$C$2:C1756, Quotations!$D$2:D1756, "")} -> 24.04 | D8: {=XLOOKUP($A8, Quotations!$E$2:E1756, Quotations!$F$2:F1756, "")} -> 111.83 | E8: {=XLOOKUP($A8, Quotations!$G$2:G1756, Quotations!$H$2:H1756, "")} -> 123.35 | F8: {=XLOOKUP($A8, Quotations!$I$2:I1756, Quotations!$J$2:J1756, "")} -> 123.96 | G8: {=XLOOKUP($A8, Quotations!$K$2:K1756, Quotations!$L$2:L1756, "")} -> 1324.9264
A9: 41649 | B9: {=XLOOKUP($A9, Quotations!$A$2:A1756, Quotations!$B$2:B1756, "")} -> 120.08 | C9: {=XLOOKUP($A9, Quotations!$C$2:C1756, Quotations!$D$2:D1756, "")} -> 24.04 | D9: {=XLOOKUP($A9, Quotations!$E$2:E1756, Quotations!$F$2:F1756, "")} -> 111.82 | E9: {=XLOOKUP($A9, Quotations!$G$2:G1756, Quotations!$H$2:H1756, "")} -> 123.16 | F9: {=XLOOKUP($A9, Quotations!$I$2:I1756, Quotations!$J$2:J1756, "")} -> 123.88 | G9: {=XLOOKUP($A9, Quotations!$K$2:K1756, Quotations!$L$2:L1756, "")} -> 1322.6834
A10: 41652 | B10: {=XLOOKUP($A10, Quotations!$A$2:A1756, Quotations!$B$2:B1756, "")} -> 120.3 | C10: {=XLOOKUP($A10, Quotations!$C$2:C1756, Quotations!$D$2:D1756, "")} -> 24.06 | D10: {=XLOOKUP($A10, Quotations!$E$2:E1756, Quotations!$F$2:F1756, "")} -> 111.84 | E10: {=XLOOKUP($A10, Quotations!$G$2:G1756, Quotations!$H$2:H1756, "")} -> 123.09 | F10: {=XLOOKUP($A10, Quotations!$I$2:I1756, Quotations!$J$2:J1756, "")} -> 123.99 | G10: {=XLOOKUP($A10, Quotations!$K$2:K1756, Quotations!$L$2:L1756, "")} -> 1326.4695
A11: 41653 | B11: {=XLOOKUP($A11, Quotations!$A$2:A1756, Quotations!$B$2:B1756, "")} -> 120.39 | C11: {=XLOOKUP($A11, Quotations!$C$2:C1756, Quotations!$D$2:D1756, "")} -> 24.05 | D11: {=XLOOKUP($A11, Quotations!$E$2:E1756, Quotations!$F$2:F1756, "")} -> 111.86 | E11: {=XLOOKUP($A11, Quotations!$G$2:G1756, Quotations!$H$2:H1756, "")} -> 123.09 | F11: {=XLOOKUP($A11, Quotations!$I$2:I1756, Quotations!$J$2:J1756, "")} -> 124.2 | G11: {=XLOOKUP($A11, Quotations!$K$2:K1756, Quotations!$L$2:L1756, "")} -> 1322.5665
A12: 41654 | B12: {=XLOOKUP($A12, Quotations!$A$2:A1756, Quotations!$B$2:B1756, "")} -> 120.89 | C12: {=XLOOKUP($A12, Quotations!$C$2:C1756, Quotations!$D$2:D1756, "")} -> 24.05 | D12: {=XLOOKUP($A12, Quotations!$E$2:E1756, Quotations!$F$2:F1756, "")} -> 111.89 | E12: {=XLOOKUP($A12, Quotations!$G$2:G1756, Quotations!$H$2:H1756, "")} -> 123.15 | F12: {=XLOOKUP($A12, Quotations!$I$2:I1756, Quotations!$J$2:J1756, "")} -> 124.37 | G12: {=XLOOKUP($A12, Quotations!$K$2:K1756, Quotations!$L$2:L1756, "")} -> 1328.9166
A13: 41655 | B13: {=XLOOKUP($A13, Quotations!$A$2:A1756, Quotations!$B$2:B1756, "")} -> 120.84 | C13: {=XLOOKUP($A13, Quotations!$C$2:C1756, Quotations!$D$2:D1756, "")} -> 24.05 | D13: {=XLOOKUP($A13, Quotations!$E$2:E1756, Quotations!$F$2:F1756, "")} -> 111.9 | E13: {=XLOOKUP($A13, Quotations!$G$2:G1756, Quotations!$H$2:H1756, "")} -> 123.05 | F13: {=XLOOKUP($A13, Quotations!$I$2:I1756, Quotations!$J$2:J1756, "")} -> 124.78 | G13: {=XLOOKUP($A13, Quotations!$K$2:K1756, Quotations!$L$2:L1756, "")} -> 1332.4553
A14: 41656 | B14: {=XLOOKUP($A14, Quotations!$A$2:A1756, Quotations!$B$2:B1756, "")} -> 121.04 | C14: {=XLOOKUP($A14, Quotations!$C$2:C1756, Quotations!$D$2:D1756, "")} -> 24.06 | D14: {=XLOOKUP($A14, Quotations!$E$2:E1756, Quotations!$F$2:F1756, "")} -> 111.96 | E14: {=XLOOKUP($A14, Quotations!$G$2:G1756, Quotations!$H$2:H1756, "")} -> 123.34 | F14: {=XLOOKUP($A14, Quotations!$I$2:I1756, Quotations!$J$2:J1756, "")} -> 124.68 | G14: {=XLOOKUP($A14, Quotations!$K$2:K1756, Quotations!$L$2:L1756, "")} -> 1332.5754
A15: 41659 | B15: {=XLOOKUP($A15, Quotations!$A$2:A1756, Quotations!$B$2:B1756, "")} -> 121.06 | C15: {=XLOOKUP($A15, Quotations!$C$2:C1756, Quotations!$D$2:D1756, "")} -> 24.06 | D15: {=XLOOKUP($A15, Quotations!$E$2:E1756, Quotations!$F$2:F1756, "")} -> 112 | E15: {=XLOOKUP($A15, Quotations!$G$2:G1756, Quotations!$H$2:H1756, "")} -> 123.51 | F15: {=XLOOKUP($A15, Quotations!$I$2:I1756, Quotations!$J$2:J1756, "")} -> 124.83 | G15: {=XLOOKUP($A15, Quotations!$K$2:K1756, Quotations!$L$2:L1756, "")} -> 1334.5886
A16: 41660 | B16: {=XLOOKUP($A16, Quotations!$A$2:A1756, Quotations!$B$2:B1756, "")} -> 120.97 | C16: {=XLOOKUP($A16, Quotations!$C$2:C1756, Quotations!$D$2:D1756, "")} -> 24.06 | D16: {=XLOOKUP($A16, Quotations!$E$2:E1756, Quotations!$F$2:F1756, "")} -> 112 | E16: {=XLOOKUP($A16, Quotations!$G$2:G1756, Quotations!$H$2:H1756, "")} -> 123.41 | F16: {=XLOOKUP($A16, Quotations!$I$2:I1756, Quotations!$J$2:J1756, "")} -> 124.74 | G16: {=XLOOKUP($A16, Quotations!$K$2:K1756, Quotations!$L$2:L1756, "")} -> 1334.2199
A17: 41661 | B17: {=XLOOKUP($A17, Quotations!$A$2:A1756, Quotations!$B$2:B1756, "")} -> 120.95 | C17: {=XLOOKUP($A17, Quotations!$C$2:C1756, Quotations!$D$2:D1756, "")} -> 24.07 | D17: {=XLOOKUP($A17, Quotations!$E$2:E1756, Quotations!$F$2:F1756, "")} -> 112.02 | E17: {=XLOOKUP($A17, Quotations!$G$2:G1756, Quotations!$H$2:H1756, "")} -> 123.38 | F17: {=XLOOKUP($A17, Quotations!$I$2:I1756, Quotations!$J$2:J1756, "")} -> 124.8 | G17: {=XLOOKUP($A17, Quotations!$K$2:K1756, Quotations!$L$2:L1756, "")} -> 1335.6941
A18: 41662 | B18: {=XLOOKUP($A18, Quotations!$A$2:A1756, Quotations!$B$2:B1756, "")} -> 120.61 | C18: {=XLOOKUP($A18, Quotations!$C$2:C1756, Quotations!$D$2:D1756, "")} -> 24.03 | D18: {=XLOOKUP($A18, Quotations!$E$2:E1756, Quotations!$F$2:F1756, "")} -> 111.99 | E18: {=XLOOKUP($A18, Quotations!$G$2:G1756, Quotations!$H$2:H1756, "")} -> 123.32 | F18: {=XLOOKUP($A18, Quotations!$I$2:I1756, Quotations!$J$2:J1756, "")} -> 124.77 | G18: {=XLOOKUP($A18, Quotations!$K$2:K1756, Quotations!$L$2:L1756, "")} -> 1338.3064
A19: 41663 | B19: {=XLOOKUP($A19, Quotations!$A$2:A1756, Quotations!$B$2:B1756, "")} -> 119.86 | C19: {=XLOOKUP($A19, Quotations!$C$2:C1756, Quotations!$D$2:D1756, "")} -> 24.02 | D19: {=XLOOKUP($A19, Quotations!$E$2:E1756, Quotations!$F$2:F1756, "")} -> 111.9 | E19: {=XLOOKUP($A19, Quotations!$G$2:G1756, Quotations!$H$2:H1756, "")} -> 122.86 | F19: {=XLOOKUP($A19, Quotations!$I$2:I1756, Quotations!$J$2:J1756, "")} -> 124.49 | G19: {=XLOOKUP($A19, Quotations!$K$2:K1756, Quotations!$L$2:L1756, "")} -> 1331.6304
A20: 41666 | B20: {=XLOOKUP($A20, Quotations!$A$2:A1756, Quotations!$B$2:B1756, "")} -> 119.61 | C20: {=XLOOKUP($A20, Quotations!$C$2:C1756, Quotations!$D$2:D1756, "")} -> 24.03 | D20: {=XLOOKUP($A20, Quotations!$E$2:E1756, Quotations!$F$2:F1756, "")} -> 111.94 | E20: {=XLOOKUP($A20, Quotations!$G$2:G1756, Quotations!$H$2:H1756, "")} -> 121.53 | F20: {=XLOOKUP($A20, Quotations!$I$2:I1756, Quotations!$J$2:J1756, "")} -> 123.96 | G20: {=XLOOKUP($A20, Quotations!$K$2:K1756, Quotations!$L$2:L1756, "")} -> 1316.1885
A21: 41667 | B21: {=XLOOKUP($A21, Quotations!$A$2:A1756, Quotations!$B$2:B1756, "")} -> 119.96 | C21: {=XLOOKUP($A21, Quotations!$C$2:C1756, Quotations!$D$2:D1756, "")} -> 24.03 | D21: {=XLOOKUP($A21, Quotations!$E$2:E1756, Quotations!$F$2:F1756, "")} -> 111.98 | E21: {=XLOOKUP($A21, Quotations!$G$2:G1756, Quotations!$H$2:H1756, "")} -> 121.5 | F21: {=XLOOKUP($A21, Quotations!$I$2:I1756, Quotations!$J$2:J1756, "")} -> 123.6 | G21: {=XLOOKUP($A21, Quotations!$K$2:K1756, Quotations!$L$2:L1756, "")} -> 1311.3099
A22: 41668 | B22: {=XLOOKUP($A22, Quotations!$A$2:A1756, Quotations!$B$2:B1756, "")} -> 119.82 | C22: {=XLOOKUP($A22, Quotations!$C$2:C1756, Quotations!$D$2:D1756, "")} -> 24.04 | D22: {=XLOOKUP($A22, Quotations!$E$2:E1756, Quotations!$F$2:F1756, "")} -> 111.93 | E22: {=XLOOKUP($A22, Quotations!$G$2:G1756, Quotations!$H$2:H1756, "")} -> 121.67 | F22: {=XLOOKUP($A22, Quotations!$I$2:I1756, Quotations!$J$2:J1756, "")} -> 123.81 | G22: {=XLOOKUP($A22, Quotations!$K$2:K1756, Quotations!$L$2:L1756, "")} -> 1319.2861
A23: 41669 | B23: {=XLOOKUP($A23, Quotations!$A$2:A1756, Quotations!$B$2:B1756, "")} -> 119.77 | C23: {=XLOOKUP($A23, Quotations!$C$2:C1756, Quotations!$D$2:D1756, "")} -> 24.06 | D23: {=XLOOKUP($A23, Quotations!$E$2:E1756, Quotations!$F$2:F1756, "")} -> 111.94 | E23: {=XLOOKUP($A23, Quotations!$G$2:G1756, Quotations!$H$2:H1756, "")} -> 121.29 | F23: {=XLOOKUP($A23, Quotations!$I$2:I1756, Quotations!$J$2:J1756, "")} -> 123.78 | G23: {=XLOOKUP($A23, Quotations!$K$2:K1756, Quotations!$L$2:L1756, "")} -> 1314.6516
A24: 41670 | B24: {=XLOOKUP($A24, Quotations!$A$2:A1756, Quotations!$B$2:B1756, "")} -> 119.68 | C24: {=XLOOKUP($A24, Quotations!$C$2:C1756, Quotations!$D$2:D1756, "")} -> 24.07 | D24: {=XLOOKUP($A24, Quotations!$E$2:E1756, Quotations!$F$2:F1756, "")} -> 111.91 | E24: {=XLOOKUP($A24, Quotations!$G$2:G1756, Quotations!$H$2:H1756, "")} -> 121.4 | F24: {=XLOOKUP($A24, Quotations!$I$2:I1756, Quotations!$J$2:J1756, "")} -> 123.79 | G24: {=XLOOKUP($A24, Quotations!$K$2:K1756, Quotations!$L$2:L1756, "")} -> 1319.4934
A25: 41673 | B25: {=XLOOKUP($A25, Quotations!$A$2:A1756, Quotations!$B$2:B1756, "")} -> 119.38 | C25: {=XLOOKUP($A25, Quotations!$C$2:C1756, Quotations!$D$2:D1756, "")} -> 24.08 | D25: {=XLOOKUP($A25, Quotations!$E$2:E1756, Quotations!$F$2:F1756, "")} -> 111.92 | E25: {=XLOOKUP($A25, Quotations!$G$2:G1756, Quotations!$H$2:H1756, "")} -> 121.2 | F25: {=XLOOKUP($A25, Quotations!$I$2:I1756, Quotations!$J$2:J1756, "")} -> 123.84 | G25: {=XLOOKUP($A25, Quotations!$K$2:K1756, Quotations!$L$2:L1756, "")} -> 1317.761
A26: 41674 | B26: {=XLOOKUP($A26, Quotations!$A$2:A1756, Quotations!$B$2:B1756, "")} -> 119.25 | C26: {=XLOOKUP($A26, Quotations!$C$2:C1756, Quotations!$D$2:D1756, "")} -> 24.09 | D26: {=XLOOKUP($A26, Quotations!$E$2:E1756, Quotations!$F$2:F1756, "")} -> 111.93 | E26: {=XLOOKUP($A26, Quotations!$G$2:G1756, Quotations!$H$2:H1756, "")} -> 120.5 | F26: {=XLOOKUP($A26, Quotations!$I$2:I1756, Quotations!$J$2:J1756, "")} -> 123.54 | G26: {=XLOOKUP($A26, Quotations!$K$2:K1756, Quotations!$L$2:L1756, "")} -> 1305.0507
A27: 41675 | B27: {=XLOOKUP($A27, Quotations!$A$2:A1756, Quotations!$B$2:B1756, "")} -> 119.32 | C27: {=XLOOKUP($A27, Quotations!$C$2:C1756, Quotations!$D$2:D1756, "")} -> 24.08 | D27: {=XLOOKUP($A27, Quotations!$E$2:E1756, Quotations!$F$2:F1756, "")} -> 111.94 | E27: {=XLOOKUP($A27, Quotations!$G$2:G1756, Quotations!$H$2:H1756, "")} -> 120.2 | F27: {=XLOOKUP($A27, Quotations!$I$2:I1756, Quotations!$J$2:J1756, "")} -> 123.29 | G27: {=XLOOKUP($A27, Quotations!$K$2:K1756, Quotations!$L$2:L1756, "")} -> 1306.6079
A28: 41676 | B28: {=XLOOKUP($A28, Quotations!$A$2:A1756, Quotations!$B$2:B1756, "")} -> 119.7 | C28: {=XLOOKUP($A28, Quotations!$C$2:C1756, Quotations!$D$2:D1756, "")} -> 24.07 | D28: {=XLOOKUP($A28, Quotations!$E$2:E1756, Quotations!$F$2:F1756, "")} -> 111.98 | E28: {=XLOOKUP($A28, Quotations!$G$2:G1756, Quotations!$H$2:H1756, "")} -> 120.19 | F28: {=XLOOKUP($A28, Quotations!$I$2:I1756, Quotations!$J$2:J1756, "")} -> 123.43 | G28: {=XLOOKUP($A28, Quotations!$K$2:K1756, Quotations!$L$2:L1756, "")} -> 1308.2034
A29: 41677 | B29: {=XLOOKUP($A29, Quotations!$A$2:A1756, Quotations!$B$2:B1756, "")} -> 120 | C29: {=XLOOKUP($A29, Quotations!$C$2:C1756, Quotations!$D$2:D1756, "")} -> 24.07 | D29: {=XLOOKUP($A29, Quotations!$E$2:E1756, Quotations!$F$2:F1756, "")} -> 111.97 | E29: {=XLOOKUP($A29, Quotations!$G$2:G1756, Quotations!$H$2:H1756, "")} -> 120.22 | F29: {=XLOOKUP($A29, Quotations!$I$2:I1756, Quotations!$J$2:J1756, "")} -> 123.95 | G29: {=XLOOKUP($A29, Quotations!$K$2:K1756, Quotations!$L$2:L1756, "")} -> 1317.5326
A30: 41680 | B30: {=XLOOKUP($A30, Quotations!$A$2:A1756, Quotations!$B$2:B1756, "")} -> 119.97 | C30: {=XLOOKUP($A30, Quotations!$C$2:C1756, Quotations!$D$2:D1756, "")} -> 24.07 | D30: {=XLOOKUP($A30, Quotations!$E$2:E1756, Quotations!$F$2:F1756, "")} -> 112 | E30: {=XLOOKUP($A30, Quotations!$G$2:G1756, Quotations!$H$2:H1756, "")} -> 120.18 | F30: {=XLOOKUP($A30, Quotations!$I$2:I1756, Quotations!$J$2:J1756, "")} -> 124.24 | G30: {=XLOOKUP($A30, Quotations!$K$2:K1756, Quotations!$L$2:L1756, "")} -> 1324.1587
A31: 41681 | B31: {=XLOOKUP($A31, Quotations!$A$2:A1756, Quotations!$B$2:B1756, "")} -> 120.42 | C31: {=XLOOKUP($A31, Quotations!$C$2:C1756, Quotations!$D$2:D1756, "")} -> 24.08 | D31: {=XLOOKUP($A31, Quotations!$E$2:E1756, Quotations!$F$2:F1756, "")} -> 112.05 | E31: {=XLOOKUP($A31, Quotations!$G$2:G1756, Quotations!$H$2:H1756, "")} -> 120.17 | F31: {=XLOOKUP($A31, Quotations!$I$2:I1756, Quotations!$J$2:J1756, "")} -> 124.35 | G31: {=XLOOKUP($A31, Quotations!$K$2:K1756, Quotations!$L$2:L1756, "")} -> 1325.7616
A32: 41682 | B32: {=XLOOKUP($A32, Quotations!$A$2:A1756, Quotations!$B$2:B1756, "")} -> 120.69 | C32: {=XLOOKUP($A32, Quotations!$C$2:C1756, Quotations!$D$2:D1756, "")} -> 24.11 | D32: {=XLOOKUP($A32, Quotations!$E$2:E1756, Quotations!$F$2:F1756, "")} -> 112.07 | E32: {=XLOOKUP($A32, Quotations!$G$2:G1756, Quotations!$H$2:H1756, "")} -> 120.23 | F32: {=XLOOKUP($A32, Quotations!$I$2:I1756, Quotations!$J$2:J1756, "")} -> 124.81 | G32: {=XLOOKUP($A32, Quotations!$K$2:K1756, Quotations!$L$2:L1756, "")} -> 1332.4847
A33: 41683 | B33: {=XLOOKUP($A33, Quotations!$A$2:A1756, Quotations!$B$2:B1756, "")} -> 120.69 | C33: {=XLOOKUP($A33, Quotations!$C$2:C1756, Quotations!$D$2:D1756, "")} -> 24.08 | D33: {=XLOOKUP($A33, Quotations!$E$2:E1756, Quotations!$F$2:F1756, "")} -> 112.05 | E33: {=XLOOKUP($A33, Quotations!$G$2:G1756, Quotations!$H$2:H1756, "")} -> 120.54 | F33: {=XLOOKUP($A33, Quotations!$I$2:I1756, Quotations!$J$2:J1756, "")} -> 124.94 | G33: {=XLOOKUP($A33, Quotations!$K$2:K1756, Quotations!$L$2:L1756, "")} -> 1334.195
A34: 41684 | B34: {=XLOOKUP($A34, Quotations!$A$2:A1756, Quotations!$B$2:B1756, "")} -> 120.99 | C34: {=XLOOKUP($A34, Quotations!$C$2:C1756, Quotations!$D$2:D1756, "")} -> 24.09 | D34: {=XLOOKUP($A34, Quotations!$E$2:E1756, Quotations!$F$2:F1756, "")} -> 112.1 | E34: {=XLOOKUP($A34, Quotations!$G$2:G1756, Quotations!$H$2:H1756, "")} -> 120.73 | F34: {=XLOOKUP($A34, Quotations!$I$2:I1756, Quotations!$J$2:J1756, "")} -> 125.03 | G34: {=XLOOKUP($A34, Quotations!$K$2:K1756, Quotations!$L$2:L1756, "")} -> 1337.2798
A35: 41687 | B35: {=XLOOKUP($A35, Quotations!$A$2:A1756, Quotations!$B$2:B1756, "")} -> 121.29 | C35: {=XLOOKUP($A35, Quotations!$C$2:C1756, Quotations!$D$2:D1756, "")} -> 24.08 | D35: {=XLOOKUP($A35, Quotations!$E$2:E1756, Quotations!$F$2:F1756, "")} -> 112.13 | E35: {=XLOOKUP($A35, Quotations!$G$2:G1756, Quotations!$H$2:H1756, "")} -> 121 | F35: {=XLOOKUP($A35, Quotations!$I$2:I1756, Quotations!$J$2:J1756, "")} -> 125.23 | G35: {=XLOOKUP($A35, Quotations!$K$2:K1756, Quotations!$L$2:L1756, "")} -> 1341.0316
A36: 41688 | B36: {=XLOOKUP($A36, Quotations!$A$2:A1756, Quotations!$B$2:B1756, "")} -> 121.34 | C36: {=XLOOKUP($A36, Quotations!$C$2:C1756, Quotations!$D$2:D1756, "")} -> 24.07 | D36: {=XLOOKUP($A36, Quotations!$E$2:E1756, Quotations!$F$2:F1756, "")} -> 112.11 | E36: {=XLOOKUP($A36, Quotations!$G$2:G1756, Quotations!$H$2:H1756, "")} -> 121.06 | F36: {=XLOOKUP($A36, Quotations!$I$2:I1756, Quotations!$J$2:J1756, "")} -> 125.38 | G36: {=XLOOKUP($A36, Quotations!$K$2:K1756, Quotations!$L$2:L1756, "")} -> 1343.233
A37: 41689 | B37: {=XLOOKUP($A37, Quotations!$A$2:A1756, Quotations!$B$2:B1756, "")} -> 121.47 | C37: {=XLOOKUP($A37, Quotations!$C$2:C1756, Quotations!$D$2:D1756, "")} -> 24.07 | D37: {=XLOOKUP($A37, Quotations!$E$2:E1756, Quotations!$F$2:F1756, "")} -> 112.12 | E37: {=XLOOKUP($A37, Quotations!$G$2:G1756, Quotations!$H$2:H1756, "")} -> 121.12 | F37: {=XLOOKUP($A37, Quotations!$I$2:I1756, Quotations!$J$2:J1756, "")} -> 125.43 | G37: {=XLOOKUP($A37, Quotations!$K$2:K1756, Quotations!$L$2:L1756, "")} -> 1346.6799
A38: 41690 | B38: {=XLOOKUP($A38, Quotations!$A$2:A1756, Quotations!$B$2:B1756, "")} -> 121.49 | C38: {=XLOOKUP($A38, Quotations!$C$2:C1756, Quotations!$D$2:D1756, "")} -> 24.06 | D38: {=XLOOKUP($A38, Quotations!$E$2:E1756, Quotations!$F$2:F1756, "")} -> 112.14 | E38: {=XLOOKUP($A38, Quotations!$G$2:G1756, Quotations!$H$2:H1756, "")} -> 121.02 | F38: {=XLOOKUP($A38, Quotations!$I$2:I1756, Quotations!$J$2:J1756, "")} -> 125.44 | G38: {=XLOOKUP($A38, Quotations!$K$2:K1756, Quotations!$L$2:L1756, "")} -> 1344.3285
A39: 41691 | B39: {=XLOOKUP($A39, Quotations!$A$2:A1756, Quotations!$B$2:B1756, "")} -> 121.78 | C39: {=XLOOKUP($A39, Quotations!$C$2:C1756, Quotations!$D$2:D1756, "")} -> 24.05 | D39: {=XLOOKUP($A39, Quotations!$E$2:E1756, Quotations!$F$2:F1756, "")} -> 112.13 | E39: {=XLOOKUP($A39, Quotations!$G$2:G1756, Quotations!$H$2:H1756, "")} -> 120.76 | F39: {=XLOOKUP($A39, Quotations!$I$2:I1756, Quotations!$J$2:J1756, "")} -> 125.43 | G39: {=XLOOKUP($A39, Quotations!$K$2:K1756, Quotations!$L$2:L1756, "")} -> 1347.5759
A40: 41694 | B40: {=XLOOKUP($A40, Quotations!$A$2:A1756, Quotations!$B$2:B1756, "")} -> 122.09 | C40: {=XLOOKUP($A40, Quotations!$C$2:C1756, Quotations!$D$2:D1756, "")} -> 24.07 | D40: {=XLOOKUP($A40, Quotations!$E$2:E1756, Quotations!$F$2:F1756, "")} -> 112.18 | E40: {=XLOOKUP($A40, Quotations!$G$2:G1756, Quotations!$H$2:H1756, "")} -> 121.01 | F40: {=XLOOKUP($A40, Quotations!$I$2:I1756, Quotations!$J$2:J1756, "")} -> 125.57 | G40: {=XLOOKUP($A40, Quotations!$K$2:K1756, Quotations!$L$2:L1756, "")} -> 1349.1462
...

Sheet IR
A1: Date | B1: Eur_1M | C1: Eur_3M | D1: Eur_6M | E1: Eur_12M
A2: 43215 | B2: -0.00371 | C2: -0.00328 | D2: -0.0027 | E2: -0.00189
A3: 43214 | B3: -0.00372 | C3: -0.00328 | D3: -0.0027 | E3: -0.00189
A4: 43213 | B4: -0.00372 | C4: -0.00328 | D4: -0.0027 | E4: -0.00189
A5: 43210 | B5: -0.00372 | C5: -0.00328 | D5: -0.00271 | E5: -0.00189
A6: 43209 | B6: -0.00372 | C6: -0.00328 | D6: -0.0027 | E6: -0.00189
A7: 43208 | B7: -0.00371 | C7: -0.00328 | D7: -0.00271 | E7: -0.00189
A8: 43207 | B8: -0.00371 | C8: -0.00328 | D8: -0.0027 | E8: -0.00189
A9: 43206 | B9: -0.00371 | C9: -0.00329 | D9: -0.0027 | E9: -0.00189
A10: 43203 | B10: -0.00371 | C10: -0.00329 | D10: -0.00271 | E10: -0.0019
A11: 43202 | B11: -0.00371 | C11: -0.00329 | D11: -0.00271 | E11: -0.00191
A12: 43201 | B12: -0.00372 | C12: -0.00329 | D12: -0.0027 | E12: -0.0019
A13: 43200 | B13: -0.00372 | C13: -0.00329 | D13: -0.00271 | E13: -0.00191
... A1041: 41730 | B1041: 0.00235 | C1041: 0.00313 | D1041: 0.00418 | E1041: 0.00591

Sheet SR
A1: Date | B1: Swap(vs6M)_2Y | C1: Swap(vs6M)_3Y | D1: Swap(vs6M)_5Y
A2: 41730 | B2: 0.004925 | C2: 0.006282 | D2: 0.009895
A3: 41731 | B3: 0.00497 | C3: 0.00642 | D3: 0.01012
A4: 41732 | B4: 0.00489 | C4: 0.006245 | D4: 0.009961
A5: 41733 | B5: 0.00466 | C5: 0.00587 | D5: 0.009361
A6: 41736 | B6: 0.00474 | C6: 0.005893 | D6: 0.009365
A7: 41737 | B7: 0.00475 | C7: 0.005998 | D7: 0.00952
A8: 41738 | B8: 0.0048 | C8: 0.005975 | D8: 0.00982
A9: 41739 | B9: 0.0046 | C9: 0.005878 | D9: 0.009429
A10: 41740 | B10: 0.004675 | C10: 0.005868 | D10: 0.009248
A11: 41743 | B11: 0.00458 | C11: 0.005798 | D11: 0.00933
A12: 41744 | B12: 0.0044 | C12: 0.005548 | D12: 0.008945
A13: 41745 | B13: 0.004473 | C13: 0.005592 | D13: 0.00902
... A1062: 43215 | B1062: -0.001288 | C1062: 0.00063 | D1062: 0.004365

Sheet Index
A1: Date | C1: Eur_1M | D1: Eur_3M | E1: Eur_6M | F1: Eur_12M | H1: Swap(vs6M)_2Y | I1: Swap(vs6M)_3Y | J1: Swap(vs6M)_5Y | L1: UBEUECR | M1: CSLOGBB | N1: CBSWBOB | O1: BNOPLPT | P1: ETHAKTE | Q1: MPCGLCA | S1: Basket Daily Returns | T1: BV Growth Factor | U1: Basket Value | W1: Realised Volatility | X1: Weighting | Z1: DI Growth Factor | AA1: Daily Index | AC1: Settlement Amount
A2: 41723 | C2: {=IFERROR( INDEX( IR!$B$2:$E2026, MATCH($A2, IR!$A$2:$A2026, 0), MATCH(C$1, IR!$B$1:$E$1, 0) ), "")} | D2: {=IFERROR( INDEX( IR!$B$2:$E2026, MATCH($A2, IR!$A$2:$A2026, 0), MATCH(D$1, IR!$B$1:$E$1, 0) ), "")} | E2: {=IFERROR( INDEX( IR!$B$2:$E2026, MATCH($A2, IR!$A$2:$A2026, 0), MATCH(E$1, IR!$B$1:$E$1, 0) ), "")} | F2: {=IFERROR( INDEX( IR!$B$2:$E2026, MATCH($A2, IR!$A$2:$A2026, 0), MATCH(F$1, IR!$B$1:$E$1, 0) ), "")} | H2: {=IFERROR( INDEX( SR!$B$2:$D2026, MATCH($A2, SR!$A$2:$A2026, 0), MATCH(H$1, SR!$B$1:$D$1, 0) ), "")} | I2: {=IFERROR( INDEX( SR!$B$2:$D2026, MATCH($A2, SR!$A$2:$A2026, 0), MATCH(I$1, SR!$B$1:$D$1, 0) ), "")} | J2: {=IFERROR( INDEX( SR!$B$2:$D2026, MATCH($A2, SR!$A$2:$A2026, 0), MATCH(J$1, SR!$B$1:$D$1, 0) ), "")} | L2: 122.35 | M2: 24.1 | N2: 112.25 | O2: 118.28 | P2: 124.74 | Q2: 1344.8619 | U2: =U3/T3 -> 99.250017
A3: 41724 | C3: {=IFERROR( INDEX( IR!$B$2:$E2026, MATCH($A3, IR!$A$2:$A2026, 0), MATCH(C$1, IR!$B$1:$E$1, 0) ), "")} | D3: {=IFERROR( INDEX( IR!$B$2:$E2026, MATCH($A3, IR!$A$2:$A2026, 0), MATCH(D$1, IR!$B$1:$E$1, 0) ), "")} | E3: {=IFERROR( INDEX( IR!$B$2:$E2026, MATCH($A3, IR!$A$2:$A2026, 0), MATCH(E$1, IR!$B$1:$E$1, 0) ), "")} | F3: {=IFERROR( INDEX( IR!$B$2:$E2026, MATCH($A3, IR!$A$2:$A2026, 0), MATCH(F$1, IR!$B$1:$E$1, 0) ), "")} | H3: {=IFERROR( INDEX( SR!$B$2:$D2026, MATCH($A3, SR!$A$2:$A2026, 0), MATCH(H$1, SR!$B$1:$D$1, 0) ), "")} | I3: {=IFERROR( INDEX( SR!$B$2:$D2026, MATCH($A3, SR!$A$2:$A2026, 0), MATCH(I$1, SR!$B$1:$D$1, 0) ), "")} | J3: {=IFERROR( INDEX( SR!$B$2:$D2026, MATCH($A3, SR!$A$2:$A2026, 0), MATCH(J$1, SR!$B$1:$D$1, 0) ), "")} | L3: 122.84 | M3: 24.11 | N3: 112.32 | O3: 118.72 | P3: 124.85 | Q3: 1348.3263 | S3: =((L3-L2)/L2)*0.1666+((M3-M2)/M2)*0.1666+((N3-N2)/N2)*0.1666+((O3-O2)/O2)*0.1666+((P3-P2)/P2)*0.1666+((Q3-Q2)/Q2)*0.1667 -> 0.0020363257 | T3: =1+S3 -> 1.0020363 | U3: =U4/T4 -> 99.452123
A4: 41725 | C4: {=IFERROR( INDEX( IR!$B$2:$E2026, MATCH($A4, IR!$A$2:$A2026, 0), MATCH(C$1, IR!$B$1:$E$1, 0) ), "")} | D4: {=IFERROR( INDEX( IR!$B$2:$E2026, MATCH($A4, IR!$A$2:$A2026, 0), MATCH(D$1, IR!$B$1:$E$1, 0) ), "")} | E4: {=IFERROR( INDEX( IR!$B$2:$E2026, MATCH($A4, IR!$A$2:$A2026, 0), MATCH(E$1, IR!$B$1:$E$1, 0) ), "")} | F4: {=IFERROR( INDEX( IR!$B$2:$E2026, MATCH($A4, IR!$A$2:$A2026, 0), MATCH(F$1, IR!$B$1:$E$1, 0) ), "")} | H4: {=IFERROR( INDEX( SR!$B$2:$D2026, MATCH($A4, SR!$A$2:$A2026, 0), MATCH(H$1, SR!$B$1:$D$1, 0) ), "")} | I4: {=IFERROR( INDEX( SR!$B$2:$D2026, MATCH($A4, SR!$A$2:$A2026, 0), MATCH(I$1, SR!$B$1:$D$1, 0) ), "")} | J4: {=IFERROR( INDEX( SR!$B$2:$D2026, MATCH($A4, SR!$A$2:$A2026, 0), MATCH(J$1, SR!$B$1:$D$1, 0) ), "")} | L4: 122.98 | M4: 24.14 | N4: 112.34 | O4: 119.09 | P4: 124.82 | Q4: 1346.6311 | S4: =((L4-L3)/L3)*0.1666+((M4-M3)/M3)*0.1666+((N4-N3)/N3)*0.1666+((O4-O3)/O3)*0.1666+((P4-P3)/P3)*0.1666+((Q4-Q3)/Q3)*0.1667 -> 0.00069644214 | T4: =1+S4 -> 1.0006964 | U4: =U5/T5 -> 99.521385
A5: 41726 | C5: {=IFERROR( INDEX( IR!$B$2:$E2026, MATCH($A5, IR!$A$2:$A2026, 0), MATCH(C$1, IR!$B$1:$E$1, 0) ), "")} | D5: {=IFERROR( INDEX( IR!$B$2:$E2026, MATCH($A5, IR!$A$2:$A2026, 0), MATCH(D$1, IR!$B$1:$E$1, 0) ), "")} | E5: {=IFERROR( INDEX( IR!$B$2:$E2026, MATCH($A5, IR!$A$2:$A2026, 0), MATCH(E$1, IR!$B$1:$E$1, 0) ), "")} | F5: {=IFERROR( INDEX( IR!$B$2:$E2026, MATCH($A5, IR!$A$2:$A2026, 0), MATCH(F$1, IR!$B$1:$E$1, 0) ), "")} | H5: {=IFERROR( INDEX( SR!$B$2:$D2026, MATCH($A5, SR!$A$2:$A2026, 0), MATCH(H$1, SR!$B$1:$D$1, 0) ), "")} | I5: {=IFERROR( INDEX( SR!$B$2:$D2026, MATCH($A5, SR!$A$2:$A2026, 0), MATCH(I$1, SR!$B$1:$D$1, 0) ), "")} | J5: {=IFERROR( INDEX( SR!$B$2:$D2026, MATCH($A5, SR!$A$2:$A2026, 0), MATCH(J$1, SR!$B$1:$D$1, 0) ), "")} | L5: 123.54 | M5: 24.13 | N5: 112.39 | O5: 119.25 | P5: 124.95 | Q5: 1345.476 | S5: =((L5-L4)/L4)*0.1666+((M5-M4)/M4)*0.1666+((N5-N4)/N4)*0.1666+((O5-O4)/O4)*0.1666+((P5-P4)/P4)*0.1666+((Q5-Q4)/Q4)*0.1667 -> 0.0010181175 | T5: =1+S5 -> 1.0010181 | U5: =U6/T6 -> 99.62271
A6: 41729 | C6: {=IFERROR( INDEX( IR!$B$2:$E2026, MATCH($A6, IR!$A$2:$A2026, 0), MATCH(C$1, IR!$B$1:$E$1, 0) ), "")} | D6: {=IFERROR( INDEX( IR!$B$2:$E2026, MATCH($A6, IR!$A$2:$A2026, 0), MATCH(D$1, IR!$B$1:$E$1, 0) ), "")} | E6: {=IFERROR( INDEX( IR!$B$2:$E2026, MATCH($A6, IR!$A$2:$A2026, 0), MATCH(E$1, IR!$B$1:$E$1, 0) ), "")} | F6: {=IFERROR( INDEX( IR!$B$2:$E2026, MATCH($A6, IR!$A$2:$A2026, 0), MATCH(F$1, IR!$B$1:$E$1, 0) ), "")} | H6: {=IFERROR( INDEX( SR!$B$2:$D2026, MATCH($A6, SR!$A$2:$A2026, 0), MATCH(H$1, SR!$B$1:$D$1, 0) ), "")} | I6: {=IFERROR( INDEX( SR!$B$2:$D2026, MATCH($A6, SR!$A$2:$A2026, 0), MATCH(I$1, SR!$B$1:$D$1, 0) ), "")} | J6: {=IFERROR( INDEX( SR!$B$2:$D2026, MATCH($A6, SR!$A$2:$A2026, 0), MATCH(J$1, SR!$B$1:$D$1, 0) ), "")} | L6: 123.6 | M6: 24.13 | N6: 112.44 | O6: 119.32 | P6: 125.07 | Q6: 1350.203 | S6: =((L6-L5)/L5)*0.1666+((M6-M5)/M5)*0.1666+((N6-N5)/N5)*0.1666+((O6-O5)/O5)*0.1666+((P6-P5)/P5)*0.1666+((Q6-Q5)/Q5)*0.1667 -> 0.0009984841 | T6: =1+S6 -> 1.0009985 | U6: =U7/T7 -> 99.722181
A7: 41730 | C7: {=IFERROR( INDEX( IR!$B$2:$E2026, MATCH($A7, IR!$A$2:$A2026, 0), MATCH(C$1, IR!$B$1:$E$1, 0) ), "")} -> 0.00235 | D7: {=IFERROR( INDEX( IR!$B$2:$E2026, MATCH($A7, IR!$A$2:$A2026, 0), MATCH(D$1, IR!$B$1:$E$1, 0) ), "")} -> 0.00313 | E7: {=IFERROR( INDEX( IR!$B$2:$E2026, MATCH($A7, IR!$A$2:$A2026, 0), MATCH(E$1, IR!$B$1:$E$1, 0) ), "")} -> 0.00418 | F7: {=IFERROR( INDEX( IR!$B$2:$E2026, MATCH($A7, IR!$A$2:$A2026, 0), MATCH(F$1, IR!$B$1:$E$1, 0) ), "")} -> 0.00591 | H7: {=IFERROR( INDEX( SR!$B$2:$D2026, MATCH($A7, SR!$A$2:$A2026, 0), MATCH(H$1, SR!$B$1:$D$1, 0) ), "")} -> 0.004925 | I7: {=IFERROR( INDEX( SR!$B$2:$D2026, MATCH($A7, SR!$A$2:$A2026, 0), MATCH(I$1, SR!$B$1:$D$1, 0) ), "")} -> 0.006282 | J7: {=IFERROR( INDEX( SR!$B$2:$D2026, MATCH($A7, SR!$A$2:$A2026, 0), MATCH(J$1, SR!$B$1:$D$1, 0) ), "")} -> 0.009895 | L7: 123.97 | M7: 24.13 | N7: 112.5 | O7: 119.16 | P7: 125.17 | Q7: 1355.4878 | S7: =((L7-L6)/L6)*0.1666+((M7-M6)/M6)*0.1666+((N7-N6)/N6)*0.1666+((O7-O6)/O6)*0.1666+((P7-P6)/P6)*0.1666+((Q7-Q6)/Q6)*0.1667 -> 0.0011499054 | T7: =1+S7 -> 1.0011499 | U7: =U8/T8 -> 99.836853
A8: 41731 | C8: {=IFERROR( INDEX( IR!$B$2:$E2026, MATCH($A8, IR!$A$2:$A2026, 0), MATCH(C$1, IR!$B$1:$E$1, 0) ), "")} -> 0.00242 | D8: {=IFERROR( INDEX( IR!$B$2:$E2026, MATCH($A8, IR!$A$2:$A2026, 0), MATCH(D$1, IR!$B$1:$E$1, 0) ), "")} -> 0.00319 | E8: {=IFERROR( INDEX( IR!$B$2:$E2026, MATCH($A8, IR!$A$2:$A2026, 0), MATCH(E$1, IR!$B$1:$E$1, 0) ), "")} -> 0.00423 | F8: {=IFERROR( INDEX( IR!$B$2:$E2026, MATCH($A8, IR!$A$2:$A2026, 0), MATCH(F$1, IR!$B$1:$E$1, 0) ), "")} -> 0.00599 | H8: {=IFERROR( INDEX( SR!$B$2:$D2026, MATCH($A8, SR!$A$2:$A2026, 0), MATCH(H$1, SR!$B$1:$D$1, 0) ), "")} -> 0.00497 | I8: {=IFERROR( INDEX( SR!$B$2:$D2026, MATCH($A8, SR!$A$2:$A2026, 0), MATCH(I$1, SR!$B$1:$D$1, 0) ), "")} -> 0.00642 | J8: {=IFERROR( INDEX( SR!$B$2:$D2026, MATCH($A8, SR!$A$2:$A2026, 0), MATCH(J$1, SR!$B$1:$D$1, 0) ), "")} -> 0.01012 | L8: 124.29 | M8: 24.13 | N8: 112.57 | O8: 119.13 | P8: 125.04 | Q8: 1363.3962 | S8: =((L8-L7)/L7)*0.1666+((M8-M7)/M7)*0.1666+((N8-N7)/N7)*0.1666+((O8-O7)/O7)*0.1666+((P8-P7)/P7)*0.1666+((Q8-Q7)/Q7)*0.1667 -> 0.0012913168 | T8: =1+S8 -> 1.0012913 | U8: =U9/T9 -> 99.965774
A9: 41732 | C9: {=IFERROR( INDEX( IR!$B$2:$E2026, MATCH($A9, IR!$A$2:$A2026, 0), MATCH(C$1, IR!$B$1:$E$1, 0) ), "")} -> 0.0024 | D9: {=IFERROR( INDEX( IR!$B$2:$E2026, MATCH($A9, IR!$A$2:$A2026, 0), MATCH(D$1, IR!$B$1:$E$1, 0) ), "")} -> 0.00319 | E9: {=IFERROR( INDEX( IR!$B$2:$E2026, MATCH($A9, IR!$A$2:$A2026, 0), MATCH(E$1, IR!$B$1:$E$1, 0) ), "")} -> 0.00423 | F9: {=IFERROR( INDEX( IR!$B$2:$E2026, MATCH($A9, IR!$A$2:$A2026, 0), MATCH(F$1, IR!$B$1:$E$1, 0) ), "")} -> 0.006 | H9: {=IFERROR( INDEX( SR!$B$2:$D2026, MATCH($A9, SR!$A$2:$A2026, 0), MATCH(H$1, SR!$B$1:$D$1, 0) ), "")} -> 0.00489 | I9: {=IFERROR( INDEX( SR!$B$2:$D2026, MATCH($A9, SR!$A$2:$A2026, 0), MATCH(I$1, SR!$B$1:$D$1, 0) ), "")} -> 0.006245 | J9: {=IFERROR( INDEX( SR!$B$2:$D2026, MATCH($A9, SR!$A$2:$A2026, 0), MATCH(J$1, SR!$B$1:$D$1, 0) ), "")} -> 0.009961 | L9: 124.57 | M9: 24.14 | N9: 112.62 | O9: 118.98 | P9: 125.15 | Q9: 1365.8854 | S9: =((L9-L8)/L8)*0.1666+((M9-M8)/M8)*0.1666+((N9-N8)/N8)*0.1666+((O9-O8)/O8)*0.1666+((P9-P8)/P8)*0.1666+((Q9-Q8)/Q8)*0.1667 -> 0.00075949715 | T9: =1+S9 -> 1.0007595 | U9: =U10/T10 -> 100.0417
A10: 41733 | C10: {=IFERROR( INDEX( IR!$B$2:$E2026, MATCH($A10, IR!$A$2:$A2026, 0), MATCH(C$1, IR!$B$1:$E$1, 0) ), "")} | D10: {=IFERROR( INDEX( IR!$B$2:$E2026, MATCH($A10, IR!$A$2:$A2026, 0), MATCH(D$1, IR!$B$1:$E$1, 0) ), "")} -> 0.00325 | E10: {=IFERROR( INDEX( IR!$B$2:$E2026, MATCH($A10, IR!$A$2:$A2026, 0), MATCH(E$1, IR!$B$1:$E$1, 0) ), "")} -> 0.00427 | F10: {=IFERROR( INDEX( IR!$B$2:$E2026, MATCH($A10, IR!$A$2:$A2026, 0), MATCH(F$1, IR!$B$1:$E$1, 0) ), "")} -> 0.00603 | H10: {=IFERROR( INDEX( SR!$B$2:$D2026, MATCH($A10, SR!$A$2:$A2026, 0), MATCH(H$1, SR!$B$1:$D$1, 0) ), "")} -> 0.00466 | I10: {=IFERROR( INDEX( SR!$B$2:$D2026, MATCH($A10, SR!$A$2:$A2026, 0), MATCH(I$1, SR!$B$1:$D$1, 0) ), "")} -> 0.00587 | J10: {=IFERROR( INDEX( SR!$B$2:$D2026, MATCH($A10, SR!$A$2:$A2026, 0), MATCH(J$1, SR!$B$1:$D$1, 0) ), "")} -> 0.009361 | L10: 124.8 | M10: 24.17 | N10: 112.67 | O10: 119.09 | P10: 125.14 | Q10: 1362.6572 | S10: =((L10-L9)/L9)*0.1666+((M10-M9)/M9)*0.1666+((N10-N9)/N9)*0.1666+((O10-O9)/O9)*0.1666+((P10-P9)/P9)*0.1666+((Q10-Q9)/Q9)*0.1667 -> 0.00033533692 | T10: =1+S10 -> 1.0003353 | U10: =U11/T11 -> 100.07524
A11: 41736 | C11: {=IFERROR( INDEX( IR!$B$2:$E2026, MATCH($A11, IR!$A$2:$A2026, 0), MATCH(C$1, IR!$B$1:$E$1, 0) ), "")} -> 0.00252 | D11: {=IFERROR( INDEX( IR!$B$2:$E2026, MATCH($A11, IR!$A$2:$A2026, 0), MATCH(D$1, IR!$B$1:$E$1, 0) ), "")} -> 0.00327 | E11: {=IFERROR( INDEX( IR!$B$2:$E2026, MATCH($A11, IR!$A$2:$A2026, 0), MATCH(E$1, IR!$B$1:$E$1, 0) ), "")} -> 0.00427 | F11: {=IFERROR( INDEX( IR!$B$2:$E2026, MATCH($A11, IR!$A$2:$A2026, 0), MATCH(F$1, IR!$B$1:$E$1, 0) ), "")} -> 0.006 | H11: {=IFERROR( INDEX( SR!$B$2:$D2026, MATCH($A11, SR!$A$2:$A2026, 0), MATCH(H$1, SR!$B$1:$D$1, 0) ), "")} -> 0.00474 | I11: {=IFERROR( INDEX( SR!$B$2:$D2026, MATCH($A11, SR!$A$2:$A2026, 0), MATCH(I$1, SR!$B$1:$D$1, 0) ), "")} -> 0.005893 | J11: {=IFERROR( INDEX( SR!$B$2:$D2026, MATCH($A11, SR!$A$2:$A2026, 0), MATCH(J$1, SR!$B$1:$D$1, 0) ), "")} -> 0.009365 | L11: 124.45 | M11: 24.16 | N11: 112.65 | O11: 119.78 | P11: 125.21 | Q11: 1358.4637 | S11: =((L11-L10)/L10)*0.1666+((M11-M10)/M10)*0.1666+((N11-N10)/N10)*0.1666+((O11-O10)/O10)*0.1666+((P11-P10)/P10)*0.1666+((Q11-Q10)/Q10)*0.1667 -> -2.0277253e-05 | T11: =1+S11 -> 0.99997972 | U11: =U12/T12 -> 100.07322
A12: 41737 | C12: {=IFERROR( INDEX( IR!$B$2:$E2026, MATCH($A12, IR!$A$2:$A2026, 0), MATCH(C$1, IR!$B$1:$E$1, 0) ), "")} -> 0.00251 | D12: {=IFERROR( INDEX( IR!$B$2:$E2026, MATCH($A12, IR!$A$2:$A2026, 0), MATCH(D$1, IR!$B$1:$E$1, 0) ), "")} -> 0.00327 | E12: {=IFERROR( INDEX( IR!$B$2:$E2026, MATCH($A12, IR!$A$2:$A2026, 0), MATCH(E$1, IR!$B$1:$E$1, 0) ), "")} -> 0.00426 | F12: {=IFERROR( INDEX( IR!$B$2:$E2026, MATCH($A12, IR!$A$2:$A2026, 0), MATCH(F$1, IR!$B$1:$E$1, 0) ), "")} -> 0.00599 | H12: {=IFERROR( INDEX( SR!$B$2:$D2026, MATCH($A12, SR!$A$2:$A2026, 0), MATCH(H$1, SR!$B$1:$D$1, 0) ), "")} -> 0.00475 | I12: {=IFERROR( INDEX( SR!$B$2:$D2026, MATCH($A12, SR!$A$2:$A2026, 0), MATCH(I$1, SR!$B$1:$D$1, 0) ), "")} -> 0.005998 | J12: {=IFERROR( INDEX( SR!$B$2:$D2026, MATCH($A12, SR!$A$2:$A2026, 0), MATCH(J$1, SR!$B$1:$D$1, 0) ), "")} -> 0.00952 | L12: 124.13 | M12: 24.15 | N12: 112.64 | O12: 119.11 | P12: 124.9 | Q12: 1349.2852 | S12: =((L12-L11)/L11)*0.1666+((M12-M11)/M11)*0.1666+((N12-N11)/N11)*0.1666+((O12-O11)/O11)*0.1666+((P12-P11)/P11)*0.1666+((Q12-Q11)/Q11)*0.1667 -> -0.0029828073 | T12: =1+S12 -> 0.99701719 | U12: =U13/T13 -> 99.774717
A13: 41738 | C13: {=IFERROR( INDEX( IR!$B$2:$E2026, MATCH($A13, IR!$A$2:$A2026, 0), MATCH(C$1, IR!$B$1:$E$1, 0) ), "")} -> 0.00251 | D13: {=IFERROR( INDEX( IR!$B$2:$E2026, MATCH($A13, IR!$A$2:$A2026, 0), MATCH(D$1, IR!$B$1:$E$1, 0) ), "")} -> 0.00327 | E13: {=IFERROR( INDEX( IR!$B$2:$E2026, MATCH($A13, IR!$A$2:$A2026, 0), MATCH(E$1, IR!$B$1:$E$1, 0) ), "")} -> 0.00427 | F13: {=IFERROR( INDEX( IR!$B$2:$E2026, MATCH($A13, IR!$A$2:$A2026, 0), MATCH(F$1, IR!$B$1:$E$1, 0) ), "")} -> 0.00599 | H13: {=IFERROR( INDEX( SR!$B$2:$D2026, MATCH($A13, SR!$A$2:$A2026, 0), MATCH(H$1, SR!$B$1:$D$1, 0) ), "")} -> 0.0048 | I13: {=IFERROR( INDEX( SR!$B$2:$D2026, MATCH($A13, SR!$A$2:$A2026, 0), MATCH(I$1, SR!$B$1:$D$1, 0) ), "")} -> 0.005975 | J13: {=IFERROR( INDEX( SR!$B$2:$D2026, MATCH($A13, SR!$A$2:$A2026, 0), MATCH(J$1, SR!$B$1:$D$1, 0) ), "")} -> 0.00982 | L13: 124.32 | M13: 24.15 | N13: 112.58 | O13: 118.8 | P13: 124.93 | Q13: 1350.5424 | S13: =((L13-L12)/L12)*0.1666+((M13-M12)/M12)*0.1666+((N13-N12)/N12)*0.1666+((O13-O12)/O12)*0.1666+((P13-P12)/P12)*0.1666+((Q13-Q12)/Q12)*0.1667 -> -7.1996072e-05 | T13: =1+S13 -> 0.999928 | U13: =U14/T14 -> 99.767533
A14: 41739 | C14: {=IFERROR( INDEX( IR!$B$2:$E2026, MATCH($A14, IR!$A$2:$A2026, 0), MATCH(C$1, IR!$B$1:$E$1, 0) ), "")} -> 0.00251 | D14: {=IFERROR( INDEX( IR!$B$2:$E2026, MATCH($A14, IR!$A$2:$A2026, 0), MATCH(D$1, IR!$B$1:$E$1, 0) ), "")} -> 0.00327 | E14: {=IFERROR( INDEX( IR!$B$2:$E2026, MATCH($A14, IR!$A$2:$A2026, 0), MATCH(E$1, IR!$B$1:$E$1, 0) ), "")} -> 0.00426 | F14: {=IFERROR( INDEX( IR!$B$2:$E2026, MATCH($A14, IR!$A$2:$A2026, 0), MATCH(F$1, IR!$B$1:$E$1, 0) ), "")} -> 0.00599 | H14: {=IFERROR( INDEX( SR!$B$2:$D2026, MATCH($A14, SR!$A$2:$A2026, 0), MATCH(H$1, SR!$B$1:$D$1, 0) ), "")} -> 0.0046 | I14: {=IFERROR( INDEX( SR!$B$2:$D2026, MATCH($A14, SR!$A$2:$A2026, 0), MATCH(I$1, SR!$B$1:$D$1, 0) ), "")} -> 0.005878 | J14: {=IFERROR( INDEX( SR!$B$2:$D2026, MATCH($A14, SR!$A$2:$A2026, 0), MATCH(J$1, SR!$B$1:$D$1, 0) ), "")} -> 0.009429 | L14: 124.19 | M14: 24.14 | N14: 112.56 | O14: 118.73 | P14: 125.06 | Q14: 1354.7371 | S14: =((L14-L13)/L13)*0.1666+((M14-M13)/M13)*0.1666+((N14-N13)/N13)*0.1666+((O14-O13)/O13)*0.1666+((P14-P13)/P13)*0.1666+((Q14-Q13)/Q13)*0.1667 -> 0.00032016189 | T14: =1+S14 -> 1.0003202 | U14: =U15/T15 -> 99.799475
A15: 41740 | C15: {=IFERROR( INDEX( IR!$B$2:$E2026, MATCH($A15, IR!$A$2:$A2026, 0), MATCH(C$1, IR!$B$1:$E$1, 0) ), "")} -> 0.00253 | D15: {=IFERROR( INDEX( IR!$B$2:$E2026, MATCH($A15, IR!$A$2:$A2026, 0), MATCH(D$1, IR!$B$1:$E$1, 0) ), "")} -> 0.00328 | E15: {=IFERROR( INDEX( IR!$B$2:$E2026, MATCH($A15, IR!$A$2:$A2026, 0), MATCH(E$1, IR!$B$1:$E$1, 0) ), "")} -> 0.00428 | F15: {=IFERROR( INDEX( IR!$B$2:$E2026, MATCH($A15, IR!$A$2:$A2026, 0), MATCH(F$1, IR!$B$1:$E$1, 0) ), "")} -> 0.00601 | H15: {=IFERROR( INDEX( SR!$B$2:$D2026, MATCH($A15, SR!$A$2:$A2026, 0), MATCH(H$1, SR!$B$1:$D$1, 0) ), "")} -> 0.004675 | I15: {=IFERROR( INDEX( SR!$B$2:$D2026, MATCH($A15, SR!$A$2:$A2026, 0), MATCH(I$1, SR!$B$1:$D$1, 0) ), "")} -> 0.005868 | J15: {=IFERROR( INDEX( SR!$B$2:$D2026, MATCH($A15, SR!$A$2:$A2026, 0), MATCH(J$1, SR!$B$1:$D$1, 0) ), "")} -> 0.009248 | L15: 123.78 | M15: 24.14 | N15: 112.55 | O15: 119.01 | P15: 124.89 | Q15: 1346.1964 | S15: =((L15-L14)/L14)*0.1666+((M15-M14)/M14)*0.1666+((N15-N14)/N14)*0.1666+((O15-O14)/O14)*0.1666+((P15-P14)/P14)*0.1666+((Q15-Q14)/Q14)*0.1667 -> -0.0014493195 | T15: =1+S15 -> 0.99855068 | U15: =U16/T16 -> 99.654834
A16: 41743 | C16: {=IFERROR( INDEX( IR!$B$2:$E2026, MATCH($A16, IR!$A$2:$A2026, 0), MATCH(C$1, IR!$B$1:$E$1, 0) ), "")} -> 0.00252 | D16: {=IFERROR( INDEX( IR!$B$2:$E2026, MATCH($A16, IR!$A$2:$A2026, 0), MATCH(D$1, IR!$B$1:$E$1, 0) ), "")} -> 0.00328 | E16: {=IFERROR( INDEX( IR!$B$2:$E2026, MATCH($A16, IR!$A$2:$A2026, 0), MATCH(E$1, IR!$B$1:$E$1, 0) ), "")} -> 0.00427 | F16: {=IFERROR( INDEX( IR!$B$2:$E2026, MATCH($A16, IR!$A$2:$A2026, 0), MATCH(F$1, IR!$B$1:$E$1, 0) ), "")} -> 0.00599 | H16: {=IFERROR( INDEX( SR!$B$2:$D2026, MATCH($A16, SR!$A$2:$A2026, 0), MATCH(H$1, SR!$B$1:$D$1, 0) ), "")} -> 0.00458 | I16: {=IFERROR( INDEX( SR!$B$2:$D2026, MATCH($A16, SR!$A$2:$A2026, 0), MATCH(I$1, SR!$B$1:$D$1, 0) ), "")} -> 0.005798 | J16: {=IFERROR( INDEX( SR!$B$2:$D2026, MATCH($A16, SR!$A$2:$A2026, 0), MATCH(J$1, SR!$B$1:$D$1, 0) ), "")} -> 0.00933 | L16: 123.62 | M16: 24.16 | N16: 112.56 | O16: 118.44 | P16: 124.51 | Q16: 1338.6179 | S16: =((L16-L15)/L15)*0.1666+((M16-M15)/M15)*0.1666+((N16-N15)/N15)*0.1666+((O16-O15)/O15)*0.1666+((P16-P15)/P15)*0.1666+((Q16-Q15)/Q15)*0.1667 -> -0.0023058108 | T16: =1+S16 -> 0.99769419 | U16: =U17/T17 -> 99.425048
A17: 41744 | C17: {=IFERROR( INDEX( IR!$B$2:$E2026, MATCH($A17, IR!$A$2:$A2026, 0), MATCH(C$1, IR!$B$1:$E$1, 0) ), "")} -> 0.00251 | D17: {=IFERROR( INDEX( IR!$B$2:$E2026, MATCH($A17, IR!$A$2:$A2026, 0), MATCH(D$1, IR!$B$1:$E$1, 0) ), "")} -> 0.00327 | E17: {=IFERROR( INDEX( IR!$B$2:$E2026, MATCH($A17, IR!$A$2:$A2026, 0), MATCH(E$1, IR!$B$1:$E$1, 0) ), "")} -> 0.00426 | F17: {=IFERROR( INDEX( IR!$B$2:$E2026, MATCH($A17, IR!$A$2:$A2026, 0), MATCH(F$1, IR!$B$1:$E$1, 0) ), "")} -> 0.00598 | H17: {=IFERROR( INDEX( SR!$B$2:$D2026, MATCH($A17, SR!$A$2:$A2026, 0), MATCH(H$1, SR!$B$1:$D$1, 0) ), "")} -> 0.0044 | I17: {=IFERROR( INDEX( SR!$B$2:$D2026, MATCH($A17, SR!$A$2:$A2026, 0), MATCH(I$1, SR!$B$1:$D$1, 0) ), "")} -> 0.005548 | J17: {=IFERROR( INDEX( SR!$B$2:$D2026, MATCH($A17, SR!$A$2:$A2026, 0), MATCH(J$1, SR!$B$1:$D$1, 0) ), "")} -> 0.008945 | L17: 123.31 | M17: 24.15 | N17: 112.52 | O17: 118.43 | P17: 124.79 | Q17: 1338.9128 | S17: =((L17-L16)/L16)*0.1666+((M17-M16)/M16)*0.1666+((N17-N16)/N16)*0.1666+((O17-O16)/O16)*0.1666+((P17-P16)/P16)*0.1666+((Q17-Q16)/Q16)*0.1667 -> -0.00014863047 | T17: =1+S17 -> 0.99985137 | U17: =U18/T18 -> 99.410271
A18: 41745 | C18: {=IFERROR( INDEX( IR!$B$2:$E2026, MATCH($A18, IR!$A$2:$A2026, 0), MATCH(C$1, IR!$B$1:$E$1, 0) ), "")} -> 0.00248 | D18: {=IFERROR( INDEX( IR!$B$2:$E2026, MATCH($A18, IR!$A$2:$A2026, 0), MATCH(D$1, IR!$B$1:$E$1, 0) ), "")} -> 0.00327 | E18: {=IFERROR( INDEX( IR!$B$2:$E2026, MATCH($A18, IR!$A$2:$A2026, 0), MATCH(E$1, IR!$B$1:$E$1, 0) ), "")} -> 0.00427 | F18: {=IFERROR( INDEX( IR!$B$2:$E2026, MATCH($A18, IR!$A$2:$A2026, 0), MATCH(F$1, IR!$B$1:$E$1, 0) ), "")} -> 0.00598 | H18: {=IFERROR( INDEX( SR!$B$2:$D2026, MATCH($A18, SR!$A$2:$A2026, 0), MATCH(H$1, SR!$B$1:$D$1, 0) ), "")} -> 0.004473 | I18: {=IFERROR( INDEX( SR!$B$2:$D2026, MATCH($A18, SR!$A$2:$A2026, 0), MATCH(I$1, SR!$B$1:$D$1, 0) ), "")} -> 0.005592 | J18: {=IFERROR( INDEX( SR!$B$2:$D2026, MATCH($A18, SR!$A$2:$A2026, 0), MATCH(J$1, SR!$B$1:$D$1, 0) ), "")} -> 0.00902 | L18: 123.69 | M18: 24.16 | N18: 112.57 | O18: 118.17 | P18: 124.75 | Q18: 1338.6974 | S18: =((L18-L17)/L17)*0.1666+((M18-M17)/M17)*0.1666+((N18-N17)/N17)*0.1666+((O18-O17)/O17)*0.1666+((P18-P17)/P17)*0.1666+((Q18-Q17)/Q17)*0.1667 -> 0.00021045023 | T18: =1+S18 -> 1.0002104 | U18: =U19/T19 -> 99.431192
A19: 41746 | C19: {=IFERROR( INDEX( IR!$B$2:$E2026, MATCH($A19, IR!$A$2:$A2026, 0), MATCH(C$1, IR!$B$1:$E$1, 0) ), "")} -> 0.00246 | D19: {=IFERROR( INDEX( IR!$B$2:$E2026, MATCH($A19, IR!$A$2:$A2026, 0), MATCH(D$1, IR!$B$1:$E$1, 0) ), "")} -> 0.00328 | E19: {=IFERROR( INDEX( IR!$B$2:$E2026, MATCH($A19, IR!$A$2:$A2026, 0), MATCH(E$1, IR!$B$1:$E$1, 0) ), "")} -> 0.00426 | F19: {=IFERROR( INDEX( IR!$B$2:$E2026, MATCH($A19, IR!$A$2:$A2026, 0), MATCH(F$1, IR!$B$1:$E$1, 0) ), "")} -> 0.00599 | H19: {=IFERROR( INDEX( SR!$B$2:$D2026, MATCH($A19, SR!$A$2:$A2026, 0), MATCH(H$1, SR!$B$1:$D$1, 0) ), "")} -> 0.00473 | I19: {=IFERROR( INDEX( SR!$B$2:$D2026, MATCH($A19, SR!$A$2:$A2026, 0), MATCH(I$1, SR!$B$1:$D$1, 0) ), "")} -> 0.00584 | J19: {=IFERROR( INDEX( SR!$B$2:$D2026, MATCH($A19, SR!$A$2:$A2026, 0), MATCH(J$1, SR!$B$1:$D$1, 0) ), "")} -> 0.009525 | L19: 123.9 | M19: 24.15 | N19: 112.62 | O19: 118.76 | P19: 125.07 | Q19: 1345.9034 | S19: =((L19-L18)/L18)*0.1666+((M19-M18)/M18)*0.1666+((N19-N18)/N18)*0.1666+((O19-O18)/O18)*0.1666+((P19-P18)/P18)*0.1666+((Q19-Q18)/Q18)*0.1667 -> 0.0024443663 | T19: =1+S19 -> 1.0024444 | U19: =U20/T20 -> 99.674238
A20: 41751 | C20: {=IFERROR( INDEX( IR!$B$2:$E2026, MATCH($A20, IR!$A$2:$A2026, 0), MATCH(C$1, IR!$B$1:$E$1, 0) ), "")} -> 0.00248 | D20: {=IFERROR( INDEX( IR!$B$2:$E2026, MATCH($A20, IR!$A$2:$A2026, 0), MATCH(D$1, IR!$B$1:$E$1, 0) ), "")} -> 0.00329 | E20: {=IFERROR( INDEX( IR!$B$2:$E2026, MATCH($A20, IR!$A$2:$A2026, 0), MATCH(E$1, IR!$B$1:$E$1, 0) ), "")} -> 0.00429 | F20: {=IFERROR( INDEX( IR!$B$2:$E2026, MATCH($A20, IR!$A$2:$A2026, 0), MATCH(F$1, IR!$B$1:$E$1, 0) ), "")} -> 0.00603 | H20: {=IFERROR( INDEX( SR!$B$2:$D2026, MATCH($A20, SR!$A$2:$A2026, 0), MATCH(H$1, SR!$B$1:$D$1, 0) ), "")} -> 0.00471 | I20: {=IFERROR( INDEX( SR!$B$2:$D2026, MATCH($A20, SR!$A$2:$A2026, 0), MATCH(I$1, SR!$B$1:$D$1, 0) ), "")} -> 0.00597 | J20: {=IFERROR( INDEX( SR!$B$2:$D2026, MATCH($A20, SR!$A$2:$A2026, 0), MATCH(J$1, SR!$B$1:$D$1, 0) ), "")} -> 0.0095 | L20: 124.39 | M20: 24.16 | N20: 112.71 | O20: 118.98 | P20: 125.05 | Q20: 1351.2213 | S20: =((L20-L19)/L19)*0.1666+((M20-M19)/M19)*0.1666+((N20-N19)/N19)*0.1666+((O20-O19)/O19)*0.1666+((P20-P19)/P19)*0.1666+((Q20-Q19)/Q19)*0.1667 -> 0.0018016358 | T20: =1+S20 -> 1.0018016 | U20: =U21/T21 -> 99.853815
A21: 41752 | C21: {=IFERROR( INDEX( IR!$B$2:$E2026, MATCH($A21, IR!$A$2:$A2026, 0), MATCH(C$1, IR!$B$1:$E$1, 0) ), "")} -> 0.00253 | D21: {=IFERROR( INDEX( IR!$B$2:$E2026, MATCH($A21, IR!$A$2:$A2026, 0), MATCH(D$1, IR!$B$1:$E$1, 0) ), "")} -> 0.00332 | E21: {=IFERROR( INDEX( IR!$B$2:$E2026, MATCH($A21, IR!$A$2:$A2026, 0), MATCH(E$1, IR!$B$1:$E$1, 0) ), "")} -> 0.00432 | F21: {=IFERROR( INDEX( IR!$B$2:$E2026, MATCH($A21, IR!$A$2:$A2026, 0), MATCH(F$1, IR!$B$1:$E$1, 0) ), "")} -> 0.00606 | H21: {=IFERROR( INDEX( SR!$B$2:$D2026, MATCH($A21, SR!$A$2:$A2026, 0), MATCH(H$1, SR!$B$1:$D$1, 0) ), "")} -> 0.0048 | I21: {=IFERROR( INDEX( SR!$B$2:$D2026, MATCH($A21, SR!$A$2:$A2026, 0), MATCH(I$1, SR!$B$1:$D$1, 0) ), "")} -> 0.00603 | J21: {=IFERROR( INDEX( SR!$B$2:$D2026, MATCH($A21, SR!$A$2:$A2026, 0), MATCH(J$1, SR!$B$1:$D$1, 0) ), "")} -> 0.00963 | L21: 124.3 | M21: 24.14 | N21: 112.68 | O21: 119.6 | P21: 125.35 | Q21: 1357.9768 | S21: =((L21-L20)/L20)*0.1666+((M21-M20)/M20)*0.1666+((N21-N20)/N20)*0.1666+((O21-O20)/O20)*0.1666+((P21-P20)/P20)*0.1666+((Q21-Q20)/Q20)*0.1667 -> 0.0017984532 | T21: =1+S21 -> 1.0017985 | U21: =U22/T22 -> 100.0334
A22: 41753 | C22: {=IFERROR( INDEX( IR!$B$2:$E2026, MATCH($A22, IR!$A$2:$A2026, 0), MATCH(C$1, IR!$B$1:$E$1, 0) ), "")} -> 0.00261 | D22: {=IFERROR( INDEX( IR!$B$2:$E2026, MATCH($A22, IR!$A$2:$A2026, 0), MATCH(D$1, IR!$B$1:$E$1, 0) ), "")} -> 0.00337 | E22: {=IFERROR( INDEX( IR!$B$2:$E2026, MATCH($A22, IR!$A$2:$A2026, 0), MATCH(E$1, IR!$B$1:$E$1, 0) ), "")} -> 0.00437 | F22: {=IFERROR( INDEX( IR!$B$2:$E2026, MATCH($A22, IR!$A$2:$A2026, 0), MATCH(F$1, IR!$B$1:$E$1, 0) ), "")} -> 0.00611 | H22: {=IFERROR( INDEX( SR!$B$2:$D2026, MATCH($A22, SR!$A$2:$A2026, 0), MATCH(H$1, SR!$B$1:$D$1, 0) ), "")} -> 0.00486 | I22: {=IFERROR( INDEX( SR!$B$2:$D2026, MATCH($A22, SR!$A$2:$A2026, 0), MATCH(I$1, SR!$B$1:$D$1, 0) ), "")} -> 0.00614 | J22: {=IFERROR( INDEX( SR!$B$2:$D2026, MATCH($A22, SR!$A$2:$A2026, 0), MATCH(J$1, SR!$B$1:$D$1, 0) ), "")} -> 0.00972 | L22: 124.31 | M22: 24.15 | N22: 112.67 | O22: 119.48 | P22: 125.23 | Q22: 1356.5453 | S22: =((L22-L21)/L21)*0.1666+((M22-M21)/M21)*0.1666+((N22-N21)/N21)*0.1666+((O22-O21)/O21)*0.1666+((P22-P21)/P21)*0.1666+((Q22-Q21)/Q21)*0.1667 -> -0.00043474014 | T22: =1+S22 -> 0.99956526 | U22: =U23/T23 -> 99.989909
A23: 41754 | C23: {=IFERROR( INDEX( IR!$B$2:$E2026, MATCH($A23, IR!$A$2:$A2026, 0), MATCH(C$1, IR!$B$1:$E$1, 0) ), "")} -> 0.00269 | D23: {=IFERROR( INDEX( IR!$B$2:$E2026, MATCH($A23, IR!$A$2:$A2026, 0), MATCH(D$1, IR!$B$1:$E$1, 0) ), "")} -> 0.00344 | E23: {=IFERROR( INDEX( IR!$B$2:$E2026, MATCH($A23, IR!$A$2:$A2026, 0), MATCH(E$1, IR!$B$1:$E$1, 0) ), "")} -> 0.00443 | F23: {=IFERROR( INDEX( IR!$B$2:$E2026, MATCH($A23, IR!$A$2:$A2026, 0), MATCH(F$1, IR!$B$1:$E$1, 0) ), "")} -> 0.00619 | H23: {=IFERROR( INDEX( SR!$B$2:$D2026, MATCH($A23, SR!$A$2:$A2026, 0), MATCH(H$1, SR!$B$1:$D$1, 0) ), "")} -> 0.004795 | I23: {=IFERROR( INDEX( SR!$B$2:$D2026, MATCH($A23, SR!$A$2:$A2026, 0), MATCH(I$1, SR!$B$1:$D$1, 0) ), "")} -> 0.006031 | J23: {=IFERROR( INDEX( SR!$B$2:$D2026, MATCH($A23, SR!$A$2:$A2026, 0), MATCH(J$1, SR!$B$1:$D$1, 0) ), "")} -> 0.009545 | L23: 124.03 | M23: 24.15 | N23: 112.57 | O23: 119.37 | P23: 125.36 | Q23: 1357.1112 | S23: =((L23-L22)/L22)*0.1666+((M23-M22)/M22)*0.1666+((N23-N22)/N22)*0.1666+((O23-O22)/O22)*0.1666+((P23-P22)/P22)*0.1666+((Q23-Q22)/Q22)*0.1667 -> -0.00043401539 | T23: =1+S23 -> 0.99956598 | U23: =U24/T24 -> 99.946511
A24: 41757 | C24: {=IFERROR( INDEX( IR!$B$2:$E2026, MATCH($A24, IR!$A$2:$A2026, 0), MATCH(C$1, IR!$B$1:$E$1, 0) ), "")} -> 0.00269 | D24: {=IFERROR( INDEX( IR!$B$2:$E2026, MATCH($A24, IR!$A$2:$A2026, 0), MATCH(D$1, IR!$B$1:$E$1, 0) ), "")} -> 0.00345 | E24: {=IFERROR( INDEX( IR!$B$2:$E2026, MATCH($A24, IR!$A$2:$A2026, 0), MATCH(E$1, IR!$B$1:$E$1, 0) ), "")} -> 0.00444 | F24: {=IFERROR( INDEX( IR!$B$2:$E2026, MATCH($A24, IR!$A$2:$A2026, 0), MATCH(F$1, IR!$B$1:$E$1, 0) ), "")} -> 0.0062 | H24: {=IFERROR( INDEX( SR!$B$2:$D2026, MATCH($A24, SR!$A$2:$A2026, 0), MATCH(H$1, SR!$B$1:$D$1, 0) ), "")} -> 0.00482 | I24: {=IFERROR( INDEX( SR!$B$2:$D2026, MATCH($A24, SR!$A$2:$A2026, 0), MATCH(I$1, SR!$B$1:$D$1, 0) ), "")} -> 0.006097 | J24: {=IFERROR( INDEX( SR!$B$2:$D2026, MATCH($A24, SR!$A$2:$A2026, 0), MATCH(J$1, SR!$B$1:$D$1, 0) ), "")} -> 0.009584 | L24: 123.87 | M24: 24.15 | N24: 112.58 | O24: 119.2 | P24: 125.2 | Q24: 1348.2083 | S24: =((L24-L23)/L23)*0.1666+((M24-M23)/M23)*0.1666+((N24-N23)/N23)*0.1666+((O24-O23)/O23)*0.1666+((P24-P23)/P23)*0.1666+((Q24-Q23)/Q23)*0.1667 -> -0.0017435967 | T24: =1+S24 -> 0.9982564 | U24: =U25/T25 -> 99.772245 | W24: {=SQRT(252/20) * SQRT( SUMSQ( LN(U3:U22 / U2:U21) ) - (1/20) * ( SUM( LN(U3:U22 / U2:U21) ) ^ 2 ) )} -> 0.021509836 | X24: =MIN(1.5, 0.06/W24) -> 1.5
A25: 41758 | C25: {=IFERROR( INDEX( IR!$B$2:$E2026, MATCH($A25, IR!$A$2:$A2026, 0), MATCH(C$1, IR!$B$1:$E$1, 0) ), "")} -> 0.00269 | D25: {=IFERROR( INDEX( IR!$B$2:$E2026, MATCH($A25, IR!$A$2:$A2026, 0), MATCH(D$1, IR!$B$1:$E$1, 0) ), "")} -> 0.00347 | E25: {=IFERROR( INDEX( IR!$B$2:$E2026, MATCH($A25, IR!$A$2:$A2026, 0), MATCH(E$1, IR!$B$1:$E$1, 0) ), "")} -> 0.00444 | F25: {=IFERROR( INDEX( IR!$B$2:$E2026, MATCH($A25, IR!$A$2:$A2026, 0), MATCH(F$1, IR!$B$1:$E$1, 0) ), "")} -> 0.00621 | H25: {=IFERROR( INDEX( SR!$B$2:$D2026, MATCH($A25, SR!$A$2:$A2026, 0), MATCH(H$1, SR!$B$1:$D$1, 0) ), "")} -> 0.00455 | I25: {=IFERROR( INDEX( SR!$B$2:$D2026, MATCH($A25, SR!$A$2:$A2026, 0), MATCH(I$1, SR!$B$1:$D$1, 0) ), "")} -> 0.00583 | J25: {=IFERROR( INDEX( SR!$B$2:$D2026, MATCH($A25, SR!$A$2:$A2026, 0), MATCH(J$1, SR!$B$1:$D$1, 0) ), "")} -> 0.00937 | L25: 124.27 | M25: 24.16 | N25: 112.64 | O25: 119.15 | P25: 125.27 | Q25: 1344.6801 | S25: =((L25-L24)/L24)*0.1666+((M25-M24)/M24)*0.1666+((N25-N24)/N24)*0.1666+((O25-O24)/O24)*0.1666+((P25-P24)/P24)*0.1666+((Q25-Q24)/Q24)*0.1667 -> 0.00028277714 | T25: =1+S25 -> 1.0002828 | U25: =U26/T26 -> 99.800458 | W25: {=SQRT(252/20) * SQRT( SUMSQ( LN(U4:U23 / U3:U22) ) - (1/20) * ( SUM( LN(U4:U23 / U3:U22) ) ^ 2 ) )} -> 0.020788635 | X25: =MIN(1.5, 0.06/W25) -> 1.5
A26: 41759 | C26: {=IFERROR( INDEX( IR!$B$2:$E2026, MATCH($A26, IR!$A$2:$A2026, 0), MATCH(C$1, IR!$B$1:$E$1, 0) ), "")} -> 0.00261 | D26: {=IFERROR( INDEX( IR!$B$2:$E2026, MATCH($A26, IR!$A$2:$A2026, 0), MATCH(D$1, IR!$B$1:$E$1, 0) ), "")} -> 0.00339 | E26: {=IFERROR( INDEX( IR!$B$2:$E2026, MATCH($A26, IR!$A$2:$A2026, 0), MATCH(E$1, IR!$B$1:$E$1, 0) ), "")} -> 0.00438 | F26: {=IFERROR( INDEX( IR!$B$2:$E2026, MATCH($A26, IR!$A$2:$A2026, 0), MATCH(F$1, IR!$B$1:$E$1, 0) ), "")} -> 0.00614 | H26: {=IFERROR( INDEX( SR!$B$2:$D2026, MATCH($A26, SR!$A$2:$A2026, 0), MATCH(H$1, SR!$B$1:$D$1, 0) ), "")} -> 0.00448 | I26: {=IFERROR( INDEX( SR!$B$2:$D2026, MATCH($A26, SR!$A$2:$A2026, 0), MATCH(I$1, SR!$B$1:$D$1, 0) ), "")} -> 0.0057 | J26: {=IFERROR( INDEX( SR!$B$2:$D2026, MATCH($A26, SR!$A$2:$A2026, 0), MATCH(J$1, SR!$B$1:$D$1, 0) ), "")} -> 0.009156 | L26: 124.25 | M26: 24.15 | N26: 112.65 | O26: 119.87 | P26: 125.59 | Q26: 1349.9078 | S26: =((L26-L25)/L25)*0.1666+((M26-M25)/M25)*0.1666+((N26-N25)/N25)*0.1666+((O26-O25)/O25)*0.1666+((P26-P25)/P25)*0.1666+((Q26-Q25)/Q25)*0.1667 -> 0.0019994067 | T26: =1+S26 -> 1.0019994 | U26: 100 | W26: {=SQRT(252/20) * SQRT( SUMSQ( LN(U5:U24 / U4:U23) ) - (1/20) * ( SUM( LN(U5:U24 / U4:U23) ) ^ 2 ) )} -> 0.021815854 | X26: =MIN(1.5, 0.06/W26) -> 1.5 | Z26: =1+X25*((U26/U25)-1)+(1-X25)*C25*((A26-A25)/360) -> 1.0029954 | AA26: 100 | AC26: =ROUNDUP( 1000*MAX(0, (AA26/100)*(1-0.011)^(4) -1), 2) -> 0
A27: 41761 | C27: {=IFERROR( INDEX( IR!$B$2:$E2026, MATCH($A27, IR!$A$2:$A2026, 0), MATCH(C$1, IR!$B$1:$E$1, 0) ), "")} -> 0.00258 | D27: {=IFERROR( INDEX( IR!$B$2:$E2026, MATCH($A27, IR!$A$2:$A2026, 0), MATCH(D$1, IR!$B$1:$E$1, 0) ), "")} -> 0.00336 | E27: {=IFERROR( INDEX( IR!$B$2:$E2026, MATCH($A27, IR!$A$2:$A2026, 0), MATCH(E$1, IR!$B$1:$E$1, 0) ), "")} -> 0.00437 | F27: {=IFERROR( INDEX( IR!$B$2:$E2026, MATCH($A27, IR!$A$2:$A2026, 0), MATCH(F$1, IR!$B$1:$E$1, 0) ), "")} -> 0.00612 | H27: {=IFERROR( INDEX( SR!$B$2:$D2026, MATCH($A27, SR!$A$2:$A2026, 0), MATCH(H$1, SR!$B$1:$D$1, 0) ), "")} -> 0.004355 | I27: {=IFERROR( INDEX( SR!$B$2:$D2026, MATCH($A27, SR!$A$2:$A2026, 0), MATCH(I$1, SR!$B$1:$D$1, 0) ), "")} -> 0.00554 | J27: {=IFERROR( INDEX( SR!$B$2:$D2026, MATCH($A27, SR!$A$2:$A2026, 0), MATCH(J$1, SR!$B$1:$D$1, 0) ), "")} -> 0.008976 | L27: 124.25 | M27: 24.15 | N27: 112.66 | O27: 120.23 | P27: 125.59 | Q27: 1353.2495 | S27: =((L27-L26)/L26)*0.1666+((M27-M26)/M26)*0.1666+((N27-N26)/N26)*0.1666+((O27-O26)/O26)*0.1666+((P27-P26)/P26)*0.1666+((Q27-Q26)/Q26)*0.1667 -> 0.00092779746 | T27: =1+S27 -> 1.0009278 | U27: =U26*T27 -> 100.09278 | W27: {=SQRT(252/20) * SQRT( SUMSQ( LN(U6:U25 / U5:U24) ) - (1/20) * ( SUM( LN(U6:U25 / U5:U24) ) ^ 2 ) )} -> 0.021584303 | X27: =MIN(1.5, 0.06/W27) -> 1.5 | Z27: =1+X26*((U27/U26)-1)+(1-X26)*C26*((A27-A26)/360) -> 1.0013844 | AA27: =AA26*Z27 -> 100.13844 | AC27: =ROUNDUP( 1000*MAX(0, (AA27/100)*(1-0.011)^(4) -1), 2) -> 0
A28: 41764 | C28: {=IFERROR( INDEX( IR!$B$2:$E2026, MATCH($A28, IR!$A$2:$A2026, 0), MATCH(C$1, IR!$B$1:$E$1, 0) ), "")} -> 0.00258 | D28: {=IFERROR( INDEX( IR!$B$2:$E2026, MATCH($A28, IR!$A$2:$A2026, 0), MATCH(D$1, IR!$B$1:$E$1, 0) ), "")} -> 0.00336 | E28: {=IFERROR( INDEX( IR!$B$2:$E2026, MATCH($A28, IR!$A$2:$A2026, 0), MATCH(E$1, IR!$B$1:$E$1, 0) ), "")} -> 0.00437 | F28: {=IFERROR( INDEX( IR!$B$2:$E2026, MATCH($A28, IR!$A$2:$A2026, 0), MATCH(F$1, IR!$B$1:$E$1, 0) ), "")} -> 0.00613 | H28: {=IFERROR( INDEX( SR!$B$2:$D2026, MATCH($A28, SR!$A$2:$A2026, 0), MATCH(H$1, SR!$B$1:$D$1, 0) ), "")} -> 0.004465 | I28: {=IFERROR( INDEX( SR!$B$2:$D2026, MATCH($A28, SR!$A$2:$A2026, 0), MATCH(I$1, SR!$B$1:$D$1, 0) ), "")} -> 0.005599 | J28: {=IFERROR( INDEX( SR!$B$2:$D2026, MATCH($A28, SR!$A$2:$A2026, 0), MATCH(J$1, SR!$B$1:$D$1, 0) ), "")} -> 0.00907 | L28: 124.26 | M28: 24.15 | N28: 112.67 | O28: 120.14 | P28: 125.74 | Q28: 1354.604 | S28: =((L28-L27)/L27)*0.1666+((M28-M27)/M27)*0.1666+((N28-N27)/N27)*0.1666+((O28-O27)/O27)*0.1666+((P28-P27)/P27)*0.1666+((Q28-Q27)/Q27)*0.1667 -> 0.00026932019 | T28: =1+S28 -> 1.0002693 | U28: =U27*T28 -> 100.11974 | W28: {=SQRT(252/20) * SQRT( SUMSQ( LN(U7:U26 / U6:U25) ) - (1/20) * ( SUM( LN(U7:U26 / U6:U25) ) ^ 2 ) )} -> 0.022376959 | X28: =MIN(1.5, 0.06/W28) -> 1.5 | Z28: =1+X27*((U28/U27)-1)+(1-X27)*C27*((A28-A27)/360) -> 1.0003932 | AA28: =AA27*Z28 -> 100.17782 | AC28: =ROUNDUP( 1000*MAX(0, (AA28/100)*(1-0.011)^(4) -1), 2) -> 0
