Workbook

Sheet Marriott
A1: MARRIOTT ANALYSIS
A3: Income statement | H3: EBIT/EBITDA & related | I3: 2024 | J3: 2023 | K3: 2022 | L3: 2021 | M3: 2020
B4: 2024 | C4: 2023 | D4: 2022 | E4: 2021 | F4: 2020 | H4: Earnings before Interest & Taxes (EBIT) | I4: =B11 -> 3844 | J4: =C11 -> 3924 | K4: =D11 -> 3474 | L4: =E11 -> 1758 | M4: =F11 -> 777
A5: Total revenues | B5: 6618 | C5: 6300 | D5: 5356 | E5: 3415 | F5: 2119 | H5: Depreciation & Amortization | I5: 183 | J5: 189 | K5: 193 | L5: 192 | M5: 478
A6: Cost of operating revenue | B6: 1383 | C6: 1354 | D6: 1267 | E6: 954 | F6: 907 | H6: Earnings before Interest, Taxes, Depreciation & Amortization (EBITDA) | I6: =I4+I5 -> 4027 | J6: =J4+J5 -> 4113 | K6: =K4+K5 -> 3667 | L6: =L4+L5 -> 1950 | M6: =M4+M5 -> 1255
A7: Gross profit | B7: =B5-B6 -> 5235 | C7: =C5-C6 -> 4946 | D7: =D5-D6 -> 4089 | E7: =E5-E6 -> 2461 | F7: =F5-F6 -> 1212 | H7: Free Cash Flow | I7: 1999 | J7: 2718 | K7: 2031 | L7: 994 | M7: 1504
A8: Selling, General & Administrative expenses | B8: 1074 | C8: 1011 | D8: 891 | E8: 823 | F8: 762
A9: Other operating expenses | B9: 317 | C9: 11 | D9: -276 | E9: -120 | F9: -327
A10: Total operating expenses | B10: =B8+B9 -> 1391 | C10: =C8+C9 -> 1022 | D10: =D8+D9 -> 615 | E10: =E8+E9 -> 703 | F10: =F8+F9 -> 435
A11: Operating profit (EBIT) | B11: =B7-B10 -> 3844 | C11: =C7-C10 -> 3924 | D11: =D7-D10 -> 3474 | E11: =E7-E10 -> 1758 | F11: =F7-F10 -> 777
A12: Net financial income | B12: -655 | C12: -535 | D12: -366 | E12: -382 | F12: -409 | H12: FINANCIAL ASSETS | I12: =I13+I16 -> 694 | J12: =J13+J16 -> 646 | K12: =K13+K16 -> 842 | L12: =L13+L16 -> 1780 | M12: =M13+M16 -> 1299
A13: Sale of Tangible & Intangible Fixed Assets | B13: 24 | C13: 24 | H13: financial investments | I13: 298 | J13: 308 | K13: 335 | L13: 387 | M13: 422
A14: Equity earnings - including non-recurring | B14: 8 | C14: 9 | D14: 18 | E14: -24 | F14: -141 | H14: current financial investments | I14: 298 | J14: 308 | K14: 335 | L14: 387 | M14: 422
A15: Other non-operating income | B15: 7 | C15: 16 | H15: non-current financial investments
A16: Normalized pre-tax profit | B16: =B11+SUM(B12:B15) -> 3228 | C16: =C11+SUM(C12:C15) -> 3438 | D16: =D11+SUM(D12:D15) -> 3126 | E16: =E11+SUM(E12:E15) -> 1352 | F16: =F11+SUM(F12:F15) -> 227 | H16: cash and cash equivalents | I16: 396 | J16: 338 | K16: 507 | L16: 1393 | M16: 877
A17: Non-Recurring Income/Expenses | B17: -77 | C17: -60 | D17: -12 | E17: -172 | F17: -693
A18: Income before taxes | B18: =B16+B17 -> 3151 | C18: =C16+C17 -> 3378 | D18: =D16+D17 -> 3114 | E18: =E16+E17 -> 1180 | F18: =F16+F17 -> -466 | H18: FINANCIAL LIABILITIES (Total Debt) | I18: =I19+I20 -> 14447 | J18: =J19+J20 -> 11873 | K18: =K19+K20 -> 10064 | L18: =L19+L20 -> 10138 | M18: =M19+M20 -> 10376
A19: Tax expenses | B19: 776 | C19: 295 | D19: 756 | E19: 81 | F19: -199 | H19: short-term debt | I19: 1309 | J19: 553 | K19: 684 | L19: 805 | M19: 1173
A20: Net income | B20: =B18-B19 -> 2375 | C20: =C18-C19 -> 3083 | D20: =D18-D19 -> 2358 | E20: =E18-E19 -> 1099 | F20: =F18-F19 -> -267 | H20: long-term loan | I20: 13138 | J20: 11320 | K20: 9380 | L20: 9333 | M20: 9203
A23: Balance sheet
B24: 2024 | C24: 2023 | D24: 2022 | E24: 2021 | F24: 2020 | H24: Net Debt (Financial liabilities - Cash&Cash Equivalents) | I24: =I18-B35 -> 14051 | J24: =J18-C35 -> 11535 | K24: =K18-D35 -> 9557 | L24: =L18-E35 -> 8745 | M24: =M18-F35 -> 9499
A25: Intangible assets | B25: 18219 | C25: 18076 | D25: 17619 | E25: 17999 | F25: 18164 | H25: Total Funds | I25: =I18+B55 -> 11455 | J25: =J18+C55 -> 11191 | K25: =K18+D55 -> 10632 | L25: =L18+E55 -> 11552 | M25: =M18+F55 -> 10806
A26: PP&E | B26: 2678 | C26: 2510 | D26: 2572 | E26: 2565 | F26: 2266 | H26: Working Capital | I26: =B36-B49 -> -5164 | J26: =C36-C49 -> -4451 | K26: =D36-D49 -> -4026 | L26: =E36-E49 -> -2781 | M26: =F36-F49 -> -2927
A27: Investments in Associates, Joint Ventures and Unconsolidated Subsidiaries | B27: 298 | C27: 308 | D27: 335 | E27: 387 | F27: 422 | H27: Net interest expenses | I27: =I28-I28 -> 0 | J27: =J28-J28 -> 0 | K27: =K28-K28 -> 0 | L27: =L28-L28 -> 0 | M27: =M28-M28 -> 0
A28: Receivables & Loans - Long-Term | B28: 136 | C28: 138 | D28: 152 | E28: 144 | F28: 159 | H28: interest expenses | I28: 695 | J28: 565 | K28: 403 | L28: 420 | M28: 445
A29: Other non-current assets | B29: 1366 | C29: 1331 | D29: 824 | E29: 832 | F29: 865 | H29: interest income | I29: 40 | J29: 30 | K29: 26 | L29: 28 | M29: 27
A30: Total fixed non-current assets | B30: =SUM(B25:B29) -> 22697 | C30: =SUM(C25:C29) -> 22363 | D30: =SUM(D25:D29) -> 21502 | E30: =SUM(E25:E29) -> 21927 | F30: =SUM(F25:F29) -> 21876
A32: Loans & Receivables | B32: 2795 | C32: 2712 | D32: 2571 | E32: 1982 | F32: 1768
A33: Prepaid Expenses - Short-Term | B33: 294 | C33: 261 | D33: 235 | E33: 251 | F33: 172
A34: Assets Held for Sale/Discontinued Operations | F34: 8
A35: Cash and cash equivalents | B35: 396 | C35: 338 | D35: 507 | E35: 1393 | F35: 877
A36: Total current assets | B36: =SUM(B32:B35) -> 3485 | C36: =SUM(C32:C35) -> 3311 | D36: =SUM(D32:D35) -> 3313 | E36: =SUM(E32:E35) -> 3626 | F36: =SUM(F32:F35) -> 2825
A37: Total ASSETS | B37: =B30+B36 -> 26182 | C37: =C30+C36 -> 25674 | D37: =D30+D36 -> 24815 | E37: =E30+E36 -> 25553 | F37: =F30+F36 -> 24701
A39: Debt - Long-Term - Total | B39: 13138 | C39: 11320 | D39: 9380 | E39: 9333 | F39: 9203
A40: Deferred Tax & Investment Tax Credits - Long-Term | B40: 81 | C40: 209 | D40: 313 | E40: 169 | F40: 83
A41: Operating Lease Liabilities - Long-Term | B41: 794 | C41: 887 | D41: 1034 | E41: 1098 | F41: 823
A42: Other Non-Current Liabilities - Total | B42: 6512 | C42: 6178 | D42: 6181 | E42: 7132 | F42: 8410
A43: Total long-term liabilities | B43: =SUM(B39:B42) -> 20525 | C43: =SUM(C39:C42) -> 18594 | D43: =SUM(D39:D42) -> 16908 | E43: =SUM(E39:E42) -> 17732 | F43: =SUM(F39:F42) -> 18519
A45: Trade Accounts Payable & Accruals - Short-Term | B45: 3749 | C45: 3776 | D45: 3235 | E45: 2930 | F45: 2663
A46: Short-Term Debt & Current Portion of Long-Term Debt | B46: 1309 | C46: 553 | D46: 684 | E46: 805 | F46: 1173
...

Sheet M.O.
A1: Mandarin Oriental
A3: Income statement | H3: EBIT/EBITDA & related | I3: 2024 | J3: 2023 | K3: 2022 | L3: 2021 | M3: 2020
B4: 2024 | C4: 2023 | D4: 2022 | E4: 2021 | F4: 2020 | H4: Earnings before Interest & Taxes (EBIT) | I4: =B11 -> 85.3 | J4: =C11 -> 102.3 | K4: =D11 -> 16.2 | L4: =E11 -> -64.6 | M4: =F11 -> -220
A5: Total revenues | B5: 525.8 | C5: 558.1 | D5: 454.1 | E5: 316.9 | F5: 183.7 | H5: Depreciation & Amortization | I5: 42.8 | J5: 51.1 | K5: 58.2 | L5: 68.5 | M5: 124.2
A6: Cost of operating revenue | B6: 282.2 | C6: 308.7 | D6: 302.7 | E6: 261.3 | F6: 233 | H6: Earnings before Interest, Taxes, Depreciation & Amortization (EBITDA) | I6: =I4+I5 -> 128.1 | J6: =J4+J5 -> 153.4 | K6: =K4+K5 -> 74.4 | L6: =L4+L5 -> 3.9 | M6: =M4+M5 -> -95.8
A7: Gross profit | B7: =B5-B6 -> 243.6 | C7: =C5-C6 -> 249.4 | D7: =D5-D6 -> 151.4 | E7: =E5-E6 -> 55.6 | F7: =F5-F6 -> -49.3 | H7: Free Cash Flow
A8: Selling, General & Administrative expenses | B8: 158.3 | C8: 152.3 | D8: 136.2 | E8: 124.8 | F8: 128.9
A9: Other operating expenses | C9: -5.2 | D9: -1 | E9: -4.6 | F9: 41.8
A10: Total operating expenses | B10: =B8+B9 -> 158.3 | C10: =C8+C9 -> 147.1 | D10: =D8+D9 -> 135.2 | E10: =E8+E9 -> 120.2 | F10: =F8+F9 -> 170.7
A11: Operating profit (EBIT) | B11: =B7-B10 -> 85.3 | C11: =C7-C10 -> 102.3 | D11: =D7-D10 -> 16.2 | E11: =E7-E10 -> -64.6 | F11: =F7-F10 -> -220
A12: Net financial income | B12: -3.9 | C12: -9.9 | D12: -14.4 | E12: -12.7 | F12: -12.6 | H12: FINANCIAL ASSETS | I12: =I13+I16 -> 2313.9 | J12: =J13+J16 -> 2253.1 | K12: =K13+K16 -> 2712.8 | L12: =L13+L16 -> 2691.3 | M12: =M13+M16 -> 2709
A13: Other non-operating income | E13: -0.8 | H13: financial investments | I13: =I14+I15 -> 2201.3 | J13: =J14+J15 -> 2144.7 | K13: =K14+K15 -> 2591.5 | L13: =L14+L15 -> 2543.4 | M13: =M14+M15 -> 2619.7
A14: Normalized pre-tax profit | B14: =B11+SUM(B12:B13) -> 81.4 | C14: =C11+SUM(C12:C13) -> 92.4 | D14: =D11+SUM(D12:D13) -> 1.8 | E14: =E11+SUM(E12:E13) -> -78.1 | F14: =F11+SUM(F12:F13) -> -232.6 | H14: current financial investments | I14: 102.4 | J14: 70.4 | K14: 104.9 | L14: 64.9 | M14: 75.3
A15: Non-Recurring Income/Expenses | B15: -142.8 | C15: -443.3 | D15: -58.5 | E15: -32.4 | F15: -436.2 | H15: non-current financial investments | I15: 2098.9 | J15: 2074.3 | K15: 2486.6 | L15: 2478.5 | M15: 2544.4
A16: Income before taxes | B16: =B14+B15 -> -61.4 | C16: =C14+C15 -> -350.9 | D16: =D14+D15 -> -56.7 | E16: =E14+E15 -> -110.5 | F16: =F14+F15 -> -668.8 | H16: cash and cash equivalents | I16: 112.6 | J16: 108.4 | K16: 121.3 | L16: 147.9 | M16: 89.3
A17: Tax expenses | B17: 30.3 | C17: 13.5 | D17: 2.1 | E17: 7.6 | F17: -19.4
A18: Net income | B18: =B16-B17 -> -91.7 | C18: =C16-C17 -> -364.4 | D18: =D16-D17 -> -58.8 | E18: =E16-E17 -> -118.1 | F18: =F16-F17 -> -649.4 | H18: FINANCIAL LIABILITIES (Total Debt) | I18: =I19+I20 -> 410.9 | J18: =J19+J20 -> 531.9 | K18: =K19+K20 -> 731.4 | L18: =L19+L20 -> 884 | M18: =M19+M20 -> 847.9
H19: short-term debt | I19: =B47 -> 109.8 | J19: =C47 -> 420.7 | K19: =D47 -> 8.1 | L19: =E47 -> 8.8 | M19: =F47 -> 71.2
H20: long-term loan | I20: =B41 -> 301.1 | J20: =C41 -> 111.2 | K20: =D41 -> 723.3 | L20: =E41 -> 875.2 | M20: =F41 -> 776.7
A21: Balance sheet
B22: 2024 | C22: 2023 | D22: 2022 | E22: 2021 | F22: 2020
A23: Intangible assets | B23: 57 | C23: 43.7 | D23: 45.7 | E23: 46.7 | F23: 45.4
A24: PP&E | B24: 805.5 | C24: 847.7 | D24: 1158.7 | E24: 1371.5 | F24: 1478.9 | H24: Net Debt (Financial liabilities - Cash&Cash Equivalents) | I24: =I18-B37 -> 195.9 | J24: =J18-C37 -> 353.1 | K24: =K18-D37 -> 505.2 | L24: =L18-E37 -> 671.2 | M24: =M18-F37 -> 683.3
A25: Investments in Associates, Joint Ventures and Unconsolidated Subsidiaries | B25: 143.2 | C25: 155.8 | D25: 203.8 | E25: 201.5 | F25: 231.6 | H25: Total Funds | I25: =I18+B59 -> 3257.1 | J25: =J18+C59 -> 3497.4 | K25: =K18+D59 -> 4029 | L25: =L18+E59 -> 4196.3 | M25: =M18+F59 -> 4361.1
A26: Receivables & Loans - Long-Term | B26: 61.4 | C26: 10.9 | D26: 12.2 | E26: 8.9 | F26: 5.1 | H26: Working Capital | I26: =B38-B52 -> 15.4 | J26: =C38-C52 -> -27.2 | K26: =D38-D52 -> 142.9 | L26: =E38-E52 -> 112.4 | M26: =F38-F52 -> 19.5
A27: Investments - Long-Term | B27: 2098.9 | C27: 2074.3 | D27: 2486.6 | E27: 2478.5 | F27: 2544.4 | H27: Net interest expenses | I27: =I28-I29 -> 3.5 | J27: =J28-J29 -> 9.3 | K27: =K28-K29 -> 12.9 | L27: =L28-L29 -> 10.9 | M27: =M28-M29 -> 11.5
A28: Other non-current assets | B28: 13.5 | C28: 14.6 | D28: 17.2 | E28: 20.8 | F28: 23.3 | H28: interest expenses | I28: 10.1 | J28: 17 | K28: 15.2 | L28: 12 | M28: 13.1
A29: Total fixed non-current assets | B29: =SUM(B23:B28) -> 3179.5 | C29: =SUM(C23:C28) -> 3147 | D29: =SUM(D23:D28) -> 3924.2 | E29: =SUM(E23:E28) -> 4127.9 | F29: =SUM(F23:F28) -> 4328.7 | H29: interest income | I29: 6.6 | J29: 7.7 | K29: 2.3 | L29: 1.1 | M29: 1.6
A31: Loans & Receivables | B31: 86.1 | C31: 60.7 | D31: 60.8 | E31: 43.6 | F31: 36
A32: Inventories - Total | B32: 5.2 | C32: 5 | D32: 5 | E32: 5.3 | F32: 6
A33: Prepaid Expenses - Short-Term | B33: 25.5 | C33: 15.4 | D33: 15.5 | E33: 15.3 | F33: 16.3
A34: Assets Held for Sale/Discontinued Operations | C34: 331.9 | H34: Net Income after Tax | I34: =B18 -> -91.7 | J34: =C18 -> -364.4 | K34: =D18 -> -58.8 | L34: =E18 -> -118.1 | M34: =F18 -> -649.4
A35: Derivative Financial Instruments - Hedging - Short-Term | B35: 0.1 | C35: 2.4 | D35: 17.4 | E35: 3.6 | H35: After Tax Income/Expense
A36: Other Current Assets - Total | B36: 5 | C36: 3.5 | D36: 3.6 | E36: 7.7 | F36: 22.5 | H36: Equity in Earnings/(Loss) of Affiliates (after Taxes) | I36: 13.13 | J36: -0.8 | K36: 9.5 | L36: -23.3 | M36: -30.5
A37: Cash and short term investments | B37: 215 | C37: 178.8 | D37: 226.2 | E37: 212.8 | F37: 164.6 | H37: Net Income
A38: Total current assets | B38: =SUM(B31:B37) -> 336.9 | C38: =SUM(C31:C37) -> 597.7 | D38: =SUM(D31:D37) -> 328.5 | E38: =SUM(E31:E37) -> 288.3 | F38: =SUM(F31:F37) -> 245.4 | H38: Income Available to Common Shares | I38: =I34+I36 -> -78.57 | J38: =J34+J36 -> -365.2 | K38: =K34+K36 -> -49.3 | L38: =L34+L36 -> -141.4 | M38: =M34+M36 -> -679.9
A39: Total ASSETS | B39: =B29+B38 -> 3516.4 | C39: =C29+C38 -> 3744.7 | D39: =D29+D38 -> 4252.7 | E39: =E29+E38 -> 4416.2 | F39: =F29+F38 -> 4574.1
A41: Debt - Long-Term - Total | B41: 301.1 | C41: 111.2 | D41: 723.3 | E41: 875.2 | F41: 776.7
A42: Deferred Tax & Investment Tax Credits - Long-Term | B42: 44.8 | C42: 42 | D42: 41.6 | E42: 50.1 | F42: 47.1
A43: Other Non-Current Liabilities - Total | B43: 2.8 | C43: 1.1 | D43: 4.6 | E43: 3.5 | F43: 11.2
...

Sheet NH
A1: NH hotels
A3: Income statement | H3: EBIT/EBITDA & related | I3: 2024 | J3: 2023 | K3: 2022 | L3: 2021 | M3: 2020
B4: 2024 | C4: 2023 | D4: 2022 | E4: 2021 | F4: 2020 | H4: Earnings before Interest & Taxes (EBIT) | I4: =B11 -> 404.5 | J4: =C11 -> 334.8 | K4: =D11 -> 252 | L4: =E11 -> -82.8 | M4: =F11 -> -332.9
A5: Total revenues | B5: 2417.9 | C5: 2159 | D5: 1722.4 | E5: 746.5 | F5: 536.2 | H5: Depreciation & Amortization | I5: 303.4 | J5: 292.3 | K5: 277.3 | L5: 280.2 | M5: 302.4
A6: Cost of operating revenue | B6: 691.1 | C6: 642.1 | D6: 569.1 | E6: 312.3 | F6: 327.8 | H6: Earnings before Interest, Taxes, Depreciation & Amortization (EBITDA) | I6: =I4+I5 -> 707.9 | J6: =J4+J5 -> 627.1 | K6: =K4+K5 -> 529.3 | L6: =L4+L5 -> 197.4 | M6: =M4+M5 -> -30.5
A7: Gross profit | B7: =B5-B6 -> 1726.8 | C7: =C5-C6 -> 1516.9 | D7: =D5-D6 -> 1153.3 | E7: =E5-E6 -> 434.2 | F7: =F5-F6 -> 208.4 | H7: Free Cash Flow
A8: Selling, General & Administrative expenses | B8: 911.6 | C8: 801.1 | D8: 621.7 | E8: 307.5 | F8: 302.3
A9: Other operating expenses | B9: 410.7 | C9: 381 | D9: 279.7 | E9: 209.5 | F9: 239
A10: Total operating expenses | B10: 1322.3 | C10: 1182.1 | D10: 901.3 | E10: 517 | F10: 541.3
A11: Operating profit (EBIT) | B11: =B7-B10 -> 404.5 | C11: =C7-C10 -> 334.8 | D11: =D7-D10 -> 252 | E11: =E7-E10 -> -82.8 | F11: =F7-F10 -> -332.9
A12: Net financial income | B12: -143.3 | C12: -129.7 | D12: -112.7 | E12: -149.2 | F12: -137.8 | H12: FINANCIAL ASSETS | I12: =I13+I16 -> 224.98 | J12: =J13+J16 -> 215.99 | K12: =K13+K16 -> 301.75 | L12: =L13+L16 -> 243.93 | M12: =M13+M16 -> 320.85
A13: Sale of Tangible & Intangible Fixed Assets | B13: 8.68 | C13: -0.24 | D13: 2.77 | E13: 65.11 | F13: -0.47 | H13: financial investments | I13: =I14+I15 -> 5.09 | J13: =J14+J15 -> 0 | K13: =K14+K15 -> 0 | L13: =L14+L15 -> 0 | M13: =M14+M15 -> 0
A14: Other non-operating income | E14: 16.69 | F14: 31.37 | H14: current financial investments | I14: 5.09
A15: Normalized pre-tax profit | B15: =B11+SUM(B12:B14) -> 269.88 | C15: =C11+SUM(C12:C14) -> 204.86 | D15: =D11+SUM(D12:D14) -> 142.07 | E15: =E11+SUM(E12:E14) -> -150.2 | F15: =F11+SUM(F12:F14) -> -439.8 | H15: non-current financial investments
A16: Non-Recurring Income/Expenses | B16: -4.01 | C16: -2.56 | D16: 14.08 | E16: 6.39 | F16: -68.21 | H16: cash and cash equivalents | I16: 219.89 | J16: 215.99 | K16: 301.75 | L16: 243.93 | M16: 320.85
A17: Income before taxes | B17: =B15+B16 -> 265.87 | C17: =C15+C16 -> 202.3 | D17: =D15+D16 -> 156.15 | E17: =E15+E16 -> -143.81 | F17: =F15+F16 -> -508.01
A18: Tax expenses | B18: 49.14 | C18: 70.32 | D18: 53.07 | E18: -9.33 | F18: -75.15 | H18: FINANCIAL LIABILITIES (Total Debt) | I18: =I19+I20 -> 2469.9 | J18: =J19+J20 -> 2441.8 | K18: =K19+K20 -> 2497 | L18: =L19+L20 -> 2738.4 | M18: =M19+M20 -> 3057.9
A19: Net income | B19: =B17-B18 -> 216.73 | C19: =C17-C18 -> 131.98 | D19: =D17-D18 -> 103.08 | E19: =E17-E18 -> -134.48 | F19: =F17-F18 -> -432.86 | H19: short-term debt | I19: =B46 -> 283.2 | J19: =C46 -> 282.5 | K19: =D46 -> 322.8 | L19: =E46 -> 280.4 | M19: =F46 -> 276.7
H20: long-term loan | I20: =B40 -> 2186.7 | J20: =C40 -> 2159.3 | K20: =D40 -> 2174.2 | L20: =E40 -> 2458 | M20: =F40 -> 2781.2
A22: Balance sheet
B23: 2024 | C23: 2023 | D23: 2022 | E23: 2021 | F23: 2020
A24: Intangible assets | B24: 278.6 | C24: 221.7 | D24: 209.8 | E24: 223.1 | F24: 229.2 | H24: Net Debt (Financial liabilities - Cash&Cash Equivalents) | I24: =I18-B36 -> 2244.9 | J24: =J18-C36 -> 2225.8 | K24: =K18-D36 -> 2195.2 | L24: =L18-E36 -> 2494.5 | M24: =M18-F36 -> 2737
A25: PP&E | B25: 3421.8 | C25: 3225.2 | D25: 3062.2 | E25: 3111.2 | F25: 3309.7 | H25: Total Funds | I25: =I18+B58 -> 3666.19 | J25: =J18+C58 -> 3451.43 | K25: =K18+D58 -> 3397.69 | L25: =L18+E58 -> 3519.49 | M25: =M18+F58 -> 3856.52
A26: Investments in Associates, Joint Ventures and Unconsolidated Subsidiaries | B26: 42.25 | C26: 43.72 | D26: 41.94 | E26: 40.92 | F26: 41.77 | H26: Working Capital | I26: =B37-B50 -> -337.97 | J26: =C37-C50 -> -338.76 | K26: =D37-D50 -> -279.62 | L26: =E37-E50 -> -210.97 | M26: =F37-F50 -> -84.2
A27: Receivables & Loans - Long-Term | E27: 27.87 | F27: 35.66 | H27: Net interest expenses | I27: =I28-I29 -> 106.59 | J27: =J28-J29 -> 104.45 | K27: =K28-K29 -> 114.64 | L27: =L28-L29 -> 121.75 | M27: =M28-M29 -> 121.15
A28: Investments - Long-Term | B28: 39.49 | C28: 36.39 | D28: 39.1 | E28: 5.24 | F28: 4.93 | H28: interest expenses | I28: 117.5 | J28: 115.2 | K28: 116.8 | L28: 122.6 | M28: 122.1
A29: Other non-current assets | B29: 255.2 | C29: 224.6 | D29: 258.4 | E29: 294 | F29: 273 | H29: interest income | I29: 10.91 | J29: 10.75 | K29: 2.16 | L29: 0.85 | M29: 0.95
A30: Total fixed non-current assets | B30: =SUM(B24:B29) -> 4037.34 | C30: =SUM(C24:C29) -> 3751.61 | D30: =SUM(D24:D29) -> 3611.44 | E30: =SUM(E24:E29) -> 3702.33 | F30: =SUM(F24:F29) -> 3894.26
A32: Loans & Receivables | B32: 208.3 | C32: 210.2 | D32: 177 | E32: 136.3 | F32: 101.4
A33: Inventories - Total | B33: 17.32 | C33: 15.3 | D33: 12.59 | E33: 9.58 | F33: 7.96
A34: Assets Held for Sale/Discontinued Operations | B34: 67.35
A35: Other Current Assets - Total | B35: 9.72 | C35: 9.55 | D35: 6.64 | E35: 13.23 | F35: 5.38
A36: Cash and short term investments | B36: 225 | C36: 216 | D36: 301.8 | E36: 243.9 | F36: 320.9
A37: Total current assets | B37: =SUM(B32:B36) -> 527.69 | C37: =SUM(C32:C36) -> 451.05 | D37: =SUM(D32:D36) -> 498.03 | E37: =SUM(E32:E36) -> 403.01 | F37: =SUM(F32:F36) -> 435.64
A38: Total ASSETS | B38: =B30+B37 -> 4565.03 | C38: =C30+C37 -> 4202.66 | D38: =D30+D37 -> 4109.47 | E38: =E30+E37 -> 4105.34 | F38: =F30+F37 -> 4329.9
A40: Debt - Long-Term - Total | B40: 2186.7 | C40: 2159.3 | D40: 2174.2 | E40: 2458 | F40: 2781.2
A41: Deferred Tax & Investment Tax Credits - Long-Term | B41: 249.2 | C41: 176.3 | D41: 192 | E41: 186.4 | F41: 171.5
A42: Other Non-Current Liabilities - Total | B42: 67.05 | C42: 67.43 | D42: 64.7 | E42: 65.93 | F42: 58.76
A43: Total long-term liabilities | B43: =SUM(B40:B42) -> 2502.95 | C43: =SUM(C40:C42) -> 2403.03 | D43: =SUM(D40:D42) -> 2430.9 | E43: =SUM(E40:E42) -> 2710.33 | F43: =SUM(F40:F42) -> 3011.46
A45: Trade Accounts Payable & Accruals - Short-Term | B45: 409.5 | C45: 405.7 | D45: 363.4 | E45: 291.5 | F45: 206.3
...

Sheet Comparison
C1: Industry Specific | I1: Marriott | O1: M.O. | U1: NH
A2: Liquidity Ratios | C2: 2024 | D2: 2023 | E2: 2022 | F2: 2021 | G2: 2020 | I2: 2024 | J2: 2023 | K2: 2022 | L2: 2021 | M2: 2020 | O2: 2024 | P2: 2023 | Q2: 2022 | R2: 2021 | S2: 2020 | U2: 2024 | V2: 2023 | W2: 2022 | X2: 2021 | Y2: 2020
A3: Current Ratio | C3: 0.9 | D3: 0.93 | E3: 1.08 | F3: 1.47 | G3: 1.82 | I3: =Marriott!B61 -> 0.40293676 | J3: =Marriott!C61 -> 0.42656532 | K3: =Marriott!D61 -> 0.4514239 | L3: =Marriott!E61 -> 0.5659435 | M3: =Marriott!F61 -> 0.49113352 | O3: =M.O.!B66 -> 1.0479005 | P3: =M.O.!C66 -> 0.95647304 | Q3: =M.O.!D66 -> 1.7699353 | R3: =M.O.!E66 -> 1.6389994 | S3: =M.O.!F66 -> 1.0863214 | U3: =NH!B65 -> 0.60958113 | V3: =NH!C65 -> 0.57108672 | W3: =NH!D65 -> 0.6404295 | X3: =NH!E65 -> 0.65638946 | Y3: =NH!F65 -> 0.83802709
A4: Cash Ratio | C4: 0.35 | D4: 0.39 | E4: 0.43 | F4: 0.69 | G4: 1.19 | I4: =Marriott!B62 -> 0.04578564 | J4: =Marriott!C62 -> 0.043545478 | K4: =Marriott!D62 -> 0.069082981 | L4: =Marriott!E62 -> 0.21741845 | M4: =Marriott!F62 -> 0.15246871 | O4: =M.O.!B67 -> 0.66874028 | P4: =M.O.!C67 -> 0.28612578 | Q4: =M.O.!D67 -> 1.21875 | R4: =M.O.!E67 -> 1.2097783 | S4: =M.O.!F67 -> 0.72864099 | U4: =NH!B66 -> 0.25991729 | V4: =NH!C66 -> 0.2734835 | W4: =NH!D66 -> 0.38809233 | X4: =NH!E66 -> 0.39724421 | Y4: =NH!F66 -> 0.61730532
A5: Quick Ratio | C5: 0.63 | D5: 0.65 | E5: 0.75 | F5: 0.88 | G5: 1.19 | I5: =Marriott!B63 -> 0.079778009 | J5: =Marriott!C63 -> 0.077170832 | K5: =Marriott!D63 -> 0.10110369 | L5: =Marriott!E63 -> 0.25659435 | M5: =Marriott!F63 -> 0.18237135 | O5: =M.O.!B68 -> 1.0317263 | P5: =M.O.!C68 -> 0.94847176 | Q5: =M.O.!D68 -> 1.7429957 | R5: =M.O.!E68 -> 1.6088687 | S5: =M.O.!F68 -> 1.059761 | U5: =NH!B67 -> 0.58957327 | V5: =NH!C67 -> 0.55171497 | W5: =NH!D67 -> 0.6242397 | X5: =NH!E67 -> 0.64078634 | Y5: =NH!F67 -> 0.82271468
A7: Profitability Ratios | C7: 2024 | D7: 2023 | E7: 2022 | F7: 2021 | G7: 2020 | I7: 2024 | J7: 2023 | K7: 2022 | L7: 2021 | M7: 2020 | O7: 2024 | P7: 2023 | Q7: 2022 | R7: 2021 | S7: 2020 | U7: 2024 | V7: 2023 | W7: 2022 | X7: 2021 | Y7: 2020
A8: Operating profit margin ratio | C8: 0.075 | D8: =0.079 -> 0.079 | E8: 0.085 | F8: 0.066 | G8: -0.166 | I8: =Marriott!B67 -> 0.58084013 | J8: =Marriott!C67 -> 0.62285714 | K8: =Marriott!D67 -> 0.64861837 | L8: =Marriott!E67 -> 0.5147877 | M8: =Marriott!F67 -> 0.3666824 | O8: =M.O.!B72 -> 0.16222898 | P8: =M.O.!C72 -> 0.18330048 | Q8: =M.O.!D72 -> 0.035674961 | R8: =M.O.!E72 -> -0.20384979 | S8: =M.O.!F72 -> -1.1976048 | U8: =NH!B71 -> 0.16729393 | V8: =NH!C71 -> 0.15507179 | W8: =NH!D71 -> 0.14630748 | X8: =NH!E71 -> -0.11091762 | Y8: =NH!F71 -> -0.62085043
A9: Return on sales | C9: 0.139 | D9: 0.148 | E9: 0.161 | F9: 0.126 | G9: -0.115 | I9: =Marriott!B69 -> 0.35886975 | J9: =Marriott!C69 -> 0.48936508 | K9: =Marriott!D69 -> 0.44025392 | L9: =Marriott!E69 -> 0.32181552 | M9: =Marriott!F69 -> -0.12600283 | O9: =M.O.!B74 -> -0.17440091 | P9: =M.O.!C74 -> -0.65292958 | Q9: =M.O.!D74 -> -0.1294869 | R9: =M.O.!E74 -> -0.37267277 | S9: =M.O.!F74 -> -3.5351116 | U9: =NH!B73 -> 0.089635634 | V9: =NH!C73 -> 0.061130153 | W9: =NH!D73 -> 0.059846726 | X9: =NH!E73 -> -0.18014735 | Y9: =NH!F73 -> -0.80727341
A10: Return on total assets | C10: 0.041 | D10: 0.038 | E10: 0.031 | F10: 0.018 | G10: -0.045 | I10: =Marriott!B73 -> 0.091599815 | J10: =Marriott!C73 -> 0.12212561 | K10: =Marriott!D73 -> 0.093630877 | L10: =Marriott!E73 -> 0.043737812 | M10: =Marriott!F73 -> -0.010733237 | O10: =M.O.!B78 -> -0.021641349 | P10: =M.O.!C78 -> -0.091329682 | Q10: =M.O.!D78 -> -0.011373992 | R10: =M.O.!E78 -> -0.031456125 | S10: =M.O.!F78 -> -0.29728253 | U10: =NH!B77 -> 0.049707506 | V10: =NH!C77 -> 0.031756 | W10: =NH!D77 -> 0.025096137 | X10: =NH!E77 -> -0.032228366 | Y10: =NH!F77 -> -0.10097066
A11: Return on investment | C11: 0.06453 | D11: 0.06993 | E11: 0.058829 | F11: -0.00097 | G11: -0.062442 | I11: =Marriott!B74 -> 0.33557399 | J11: =Marriott!C74 -> 0.35063891 | K11: =Marriott!D74 -> 0.32674944 | L11: =Marriott!E74 -> 0.15218144 | M11: =Marriott!F74 -> 0.071904497 | O11: =M.O.!B79 -> 0.026188941 | P11: =M.O.!C79 -> 0.0292503 | Q11: =M.O.!D79 -> 0.0040208488 | R11: =M.O.!E79 -> -0.015394514 | S11: =M.O.!F79 -> -0.050445988 | U11: =NH!B78 -> 0.11033253 | V11: =NH!C78 -> 0.097003271 | W11: =NH!D78 -> 0.074168038 | X11: =NH!E78 -> -0.023526136 | Y11: =NH!F78 -> -0.086321347
A12: Return on equity | C12: 0.115 | D12: 0.097 | E12: 0.065 | F12: -0.021 | G12: -0.246 | I12: =Marriott!B75 -> -1.2928688 | J12: =Marriott!C75 -> -54.087719 | K12: =Marriott!D75 -> 2.3794147 | L12: =Marriott!E75 -> 1.191974 | M12: =Marriott!F75 -> -0.47131509 | O12: =M.O.!B80 -> -0.027085632 | P12: =M.O.!C80 -> -0.11668719 | Q12: =M.O.!D80 -> -0.015038847 | R12: =M.O.!E80 -> -0.041579279 | S12: =M.O.!F80 -> -0.17849 | U12: =NH!B79 -> 0.2013537 | V12: =NH!C79 -> 0.14043794 | W12: =NH!D79 -> 0.12378167 | X12: =NH!E79 -> -0.18820765 | Y12: =NH!F79 -> -0.44509667
A13: Sales growth ratio | C13: 0.07023 | D13: 0.08233 | E13: 0.6979 | F13: 0.7839 | G13: -0.7038 | I13: =Marriott!B77 -> 0.05047619 | J13: =Marriott!C77 -> 0.17625093 | K13: =Marriott!D77 -> 0.56837482 | L13: =Marriott!E77 -> 0.61160925 | M13: =Marriott!F77 -> -0.6056207 | O13: =M.O.!B82 -> -0.057874933 | P13: =M.O.!C82 -> 0.22902444 | Q13: =M.O.!D82 -> 0.43294415 | R13: =M.O.!E82 -> 0.72509526 | S13: =M.O.!F82 -> -0.89245234 | U13: =NH!B81 -> 0.11991663 | V13: =NH!C81 -> 0.25348351 | W13: =NH!D81 -> 1.3073007 | X13: =NH!E81 -> 0.3922044 | Y13: =NH!F81 -> -0.68608028
A15: Debt Ratios | C15: 2024 | D15: 2023 | E15: 2022 | F15: 2021 | G15: 2020 | I15: 2024 | J15: 2023 | K15: 2022 | L15: 2021 | M15: 2020 | O15: 2024 | P15: 2023 | Q15: 2022 | R15: 2021 | S15: 2020 | U15: 2024 | V15: 2023 | W15: 2022 | X15: 2021 | Y15: 2020
A16: Debt to asset ratio | C16: 0.79 | D16: 0.81 | E16: 0.83 | F16: 0.76 | G16: 0.81 | I16: =Marriott!B81 -> 0.55179131 | J16: =Marriott!C81 -> 0.46245229 | K16: =Marriott!D81 -> 0.40556115 | L16: =Marriott!E81 -> 0.39674402 | M16: =Marriott!F81 -> 0.42006396 | O16: =M.O.!B86 -> 0.11685246 | P16: =M.O.!C86 -> 0.14204075 | Q16: =M.O.!D86 -> 0.17198486 | R16: =M.O.!E86 -> 0.20017209 | S16: =M.O.!F86 -> 0.1853698 | U16: =NH!B85 -> 0.54104792 | V16: =NH!C85 -> 0.58101298 | W16: =NH!D85 -> 0.60762093 | X16: =NH!E85 -> 0.66703367 | Y16: =NH!F85 -> 0.70622878
A17: Debt to equity ratio | C17: 3.22 | D17: 3.11 | E17: 2.78 | F17: 2.71 | G17: 2.6 | I17: =Marriott!B83 -> 4.8285428 | J17: =Marriott!C83 -> 17.409091 | K17: =Marriott!D83 -> 17.71831 | L17: =Marriott!E83 -> 7.1697313 | M17: =Marriott!F83 -> 24.130233 | O17: =M.O.!B88 -> 0.14436793 | P17: =M.O.!C88 -> 0.17936267 | Q17: =M.O.!D88 -> 0.22179767 | R17: =M.O.!E88 -> 0.26688404 | S17: =M.O.!F88 -> 0.24134692 | U17: =NH!B87 -> 2.0646332 | V17: =NH!C87 -> 2.4185098 | W17: =NH!D87 -> 2.772319 | X17: =NH!E87 -> 3.50587 | Y17: =NH!F87 -> 3.82898
A18: Total debt to capitalization ratio | C18: 0.4346 | D18: 0.388 | E18: 0.3856 | F18: 0.4314 | G18: 0.4669 | I18: =Marriott!B82 -> 1.261196 | J18: =Marriott!C82 -> 1.0609418 | K18: =Marriott!D82 -> 0.94657637 | L18: =Marriott!E82 -> 0.87759695 | M18: =Marriott!F82 -> 0.96020729 | O18: =M.O.!B87 -> 0.12615517 | P18: =M.O.!C87 -> 0.15208441 | Q18: =M.O.!D87 -> 0.18153388 | R18: =M.O.!E87 -> 0.21066177 | S18: =M.O.!F87 -> 0.19442343 | U18: =NH!B86 -> 0.67369667 | V18: =NH!C86 -> 0.70747487 | W18: =NH!D86 -> 0.73491107 | X18: =NH!E86 -> 0.77806728 | Y18: =NH!F86 -> 0.79291693
A19: Interest coverage ratio | C19: 3.95 | D19: 3.35 | E19: 2.52 | F19: 1.8 | G19: -2.34 | I19: =Marriott!B84 -> 5.5309353 | J19: =Marriott!C84 -> 6.9451327 | K19: =Marriott!D84 -> 8.6203474 | L19: =Marriott!E84 -> 4.1857143 | M19: =Marriott!F84 -> 1.7460674 | O19: =M.O.!B89 -> 8.4455446 | P19: =M.O.!C89 -> 6.0176471 | Q19: =M.O.!D89 -> 1.0657895 | R19: =M.O.!E89 -> -5.3833333 | S19: =M.O.!F89 -> -16.793893 | U19: =NH!B88 -> 3.4425532 | V19: =NH!C88 -> 2.90625 | W19: =NH!D88 -> 2.1575342 | X19: =NH!E88 -> -0.67536705 | Y19: =NH!F88 -> -2.7264537
A21: Operating Ratio | C21: 2024 | D21: 2023 | E21: 2022 | F21: 2021 | G21: 2020 | I21: 2024 | J21: 2023 | K21: 2022 | L21: 2021 | M21: 2020 | O21: 2024 | P21: 2023 | Q21: 2022 | R21: 2021 | S21: 2020 | U21: 2024 | V21: 2023 | W21: 2022 | X21: 2021 | Y21: 2020
A22: Fixed Asset Turnover Ratio | C22: 0.4356 | D22: 0.4338 | E22: 0.3999 | F22: 0.234 | G22: 0.1257 | I22: =Marriott!B88 -> 0.29374168 | J22: =Marriott!C88 -> 0.28724496 | K22: =Marriott!D88 -> 0.24665546 | L22: =Marriott!E88 -> 0.15592539 | M22: =Marriott!F88 -> 0.096757991 | O22: =M.O.!B93 -> 0.16622145 | P22: =M.O.!C93 -> 0.15785157 | Q22: =M.O.!D93 -> 0.11279045 | R22: =M.O.!E93 -> 0.074947378 | S22: =M.O.!F93 -> 0.040545611 | U22: =NH!B92 -> 0.40890254 | V22: =NH!C92 -> 0.38849591 | W22: =NH!D92 -> 0.31530744 | X22: =NH!E92 -> 0.13213652 | Y22: =NH!F92 -> 0.09196112
A24: Efficiency Ratio | C24: 2024 | D24: 2023 | E24: 2022 | F24: 2021 | G24: 2020 | I24: 2024 | J24: 2023 | K24: 2022 | L24: 2021 | M24: 2020 | O24: 2024 | P24: 2023 | Q24: 2022 | R24: 2021 | S24: 2020 | U24: 2024 | V24: 2023 | W24: 2022 | X24: 2021 | Y24: 2020
A25: Days' inventory on hand ratio | C25: 7 | D25: 6 | E25: 8 | F25: 9 | G25: 13 | O25: =M.O.!B102 -> 6.6144578 | P25: =M.O.!C102 -> 5.9280855 | Q25: =M.O.!D102 -> 6.2269574 | R25: =M.O.!E102 -> 7.9138921 | S25: =M.O.!F102 -> 13.448536
A26: Accounts receivable turnover ratio | C26: 72.32 | D26: 67.57 | E26: 62.43 | F26: 36.77 | G26: 20.61 | I26: =Marriott!B92 -> 2.4034865 | J26: =Marriott!C92 -> 2.3850085 | K26: =Marriott!D92 -> 2.3527345 | L26: =Marriott!E92 -> 1.8213333 | M26: =Marriott!F92 -> 1.0180159 | O26: =M.O.!B97 -> 7.1634877 | P26: =M.O.!C97 -> 9.1868313 | Q26: =M.O.!D97 -> 8.6992337 | R26: =M.O.!E97 -> 7.9623116 | S26: =M.O.!F97 -> 3.8796199 | U26: =NH!B96 -> 11.555078 | V26: =NH!C96 -> 11.15186 | W26: =NH!D96 -> 10.995212 | X26: =NH!E96 -> 6.2810265 | Y26: =NH!F96 -> 10.575937
A27: Accounts receivable days on hand | C27: 22 | D27: 19 | E27: 23 | F27: 19 | G27: 48 | I27: =Marriott!B93 -> 152.27879 | J27: =Marriott!C93 -> 153.45857 | K27: =Marriott!D93 -> 155.56367 | L27: =Marriott!E93 -> 200.95168 | M27: =Marriott!F93 -> 359.52289 | O27: =M.O.!B98 -> 51.092431 | P27: =M.O.!C98 -> 39.839634 | Q27: =M.O.!D98 -> 42.072671 | R27: =M.O.!E98 -> 45.966551 | S27: =M.O.!F98 -> 94.33914 | U27: =NH!B97 -> 31.674387 | V27: =NH!C97 -> 32.819639 | W27: =NH!D97 -> 33.287216 | X27: =NH!E97 -> 58.27073 | Y27: =NH!F97 -> 34.606863
A28: Accounts payable turnover ratio | C28: 10.63 | D28: 9.5923 | E28: 21.47 | F28: 37.0513 | G28: 9.706 | I28: =Marriott!B94 -> 1.8427715 | J28: =Marriott!C94 -> 1.8247978 | K28: =Marriott!D94 -> 1.7214674 | L28: =Marriott!E94 -> 1.5227454 | M28: =Marriott!F94 -> 1.4546913 | O28: =M.O.!B99 -> 1.62886 | P28: =M.O.!C99 -> 1.9470199 | Q28: =M.O.!D99 -> 3.4417283 | R28: =M.O.!E99 -> 16.433962 | S28: =M.O.!F99 -> 12.73224 | U28: =NH!B98 -> 2.3134526 | V28: =NH!C98 -> 2.2689527 | W28: =NH!D98 -> 2.2985302 | X28: =NH!E98 -> 1.5804496 | Y28: =NH!F98 -> 1.5533189
A29: Accounts payable days on hand | C29: 34.43 | D29: 38.06 | E29: 17.0004 | F29: 9.8512 | G29: 37.7086 | I29: =Marriott!B95 -> 198.61388 | J29: =Marriott!C95 -> 200.57016 | K29: =Marriott!D95 -> 212.60931 | L29: =Marriott!E95 -> 240.35535 | M29: =Marriott!F95 -> 251.59978 | O29: =M.O.!B100 -> 224.69702 | P29: =M.O.!C100 -> 187.97959 | Q29: =M.O.!D100 -> 106.34192 | R29: =M.O.!E100 -> 22.270953 | S29: =M.O.!F100 -> 28.745923 | U29: =NH!B99 -> 158.2051 | V29: =NH!C99 -> 161.3079 | W29: =NH!D99 -> 159.23219 | X29: =NH!E99 -> 231.57967 | Y29: =NH!F99 -> 235.6245
A30: Operating expense ratio | C30: 0.2635 | D30: 0.2713 | E30: 0.2886 | F30: 0.101 | G30: -0.1895
A31: Total asset turnover ratio | C31: 0.4356 | D31: 0.4338 | E31: 0.3999 | F31: 0.234 | G31: 0.1257 | I31: =Marriott!B89 -> 0.25524529 | J31: =Marriott!C89 -> 0.24955931 | K31: =Marriott!D89 -> 0.21267471 | L31: =Marriott!E89 -> 0.13590958 | M31: =Marriott!F89 -> 0.085182505 | O31: =M.O.!B94 -> 0.14482654 | P31: =M.O.!C94 -> 0.13957036 | Q31: =M.O.!D94 -> 0.10476531 | R31: =M.O.!E94 -> 0.070498204 | S31: =M.O.!F94 -> 0.03794357 | U31: =NH!B93 -> 0.5515571 | V31: =NH!C93 -> 0.51949452 | W31: =NH!D93 -> 0.41934989 | X31: =NH!E93 -> 0.17699577 | Y31: =NH!F93 -> 0.12295607

Sheet Liquidity Graphs
A1: Current Ratio | B1: 2024 | C1: 2023 | D1: 2022 | E1: 2021 | F1: 2020
A2: Industry | B2: =Comparison!C3 -> 0.9 | C2: =Comparison!D3 -> 0.93 | D2: =Comparison!E3 -> 1.08 | E2: =Comparison!F3 -> 1.47 | F2: =Comparison!G3 -> 1.82
A3: Marriott | B3: =Comparison!I3 -> 0.40293676 | C3: =Comparison!J3 -> 0.42656532 | D3: =Comparison!K3 -> 0.4514239 | E3: =Comparison!L3 -> 0.5659435 | F3: =Comparison!M3 -> 0.49113352
A4: M.O. | B4: =Comparison!O3 -> 1.0479005 | C4: =Comparison!P3 -> 0.95647304 | D4: =Comparison!Q3 -> 1.7699353 | E4: =Comparison!R3 -> 1.6389994 | F4: =Comparison!S3 -> 1.0863214
A5: NH | B5: =Comparison!U3 -> 0.60958113 | C5: =Comparison!V3 -> 0.57108672 | D5: =Comparison!W3 -> 0.6404295 | E5: =Comparison!X3 -> 0.65638946 | F5: =Comparison!Y3 -> 0.83802709
A18: Cash Ratio | B18: 2024 | C18: 2023 | D18: 2022 | E18: 2021 | F18: 2020
A19: Industry | B19: =Comparison!C4 -> 0.35 | C19: =Comparison!D4 -> 0.39 | D19: =Comparison!E4 -> 0.43 | E19: =Comparison!F4 -> 0.69 | F19: =Comparison!G4 -> 1.19
A20: Marriott | B20: =Comparison!I4 -> 0.04578564 | C20: =Comparison!J4 -> 0.043545478 | D20: =Comparison!K4 -> 0.069082981 | E20: =Comparison!L4 -> 0.21741845 | F20: =Comparison!M4 -> 0.15246871
A21: M.O. | B21: =Comparison!O4 -> 0.66874028 | C21: =Comparison!P4 -> 0.28612578 | D21: =Comparison!Q4 -> 1.21875 | E21: =Comparison!R4 -> 1.2097783 | F21: =Comparison!S4 -> 0.72864099
A22: NH | B22: =Comparison!U4 -> 0.25991729 | C22: =Comparison!V4 -> 0.2734835 | D22: =Comparison!W4 -> 0.38809233 | E22: =Comparison!X4 -> 0.39724421 | F22: =Comparison!Y4 -> 0.61730532
A35: Quick Ratio | B35: 2024 | C35: 2023 | D35: 2022 | E35: 2021 | F35: 2020
A36: Industry | B36: =Comparison!C5 -> 0.63 | C36: =Comparison!D5 -> 0.65 | D36: =Comparison!E5 -> 0.75 | E36: =Comparison!F5 -> 0.88 | F36: =Comparison!G5 -> 1.19
A37: Marriott | B37: =Comparison!I5 -> 0.079778009 | C37: =Comparison!J5 -> 0.077170832 | D37: =Comparison!K5 -> 0.10110369 | E37: =Comparison!L5 -> 0.25659435 | F37: =Comparison!M5 -> 0.18237135
A38: M.O. | B38: =Comparison!O5 -> 1.0317263 | C38: =Comparison!P5 -> 0.94847176 | D38: =Comparison!Q5 -> 1.7429957 | E38: =Comparison!R5 -> 1.6088687 | F38: =Comparison!S5 -> 1.059761
A39: NH | B39: =Comparison!U5 -> 0.58957327 | C39: =Comparison!V5 -> 0.55171497 | D39: =Comparison!W5 -> 0.6242397 | E39: =Comparison!X5 -> 0.64078634 | F39: =Comparison!Y5 -> 0.82271468

Sheet Efficiency Graphs
A1: Operating Profit Margin Ratio | B1: 2024 | C1: 2023 | D1: 2022 | E1: 2021 | F1: 2020
A2: Industry | B2: =Comparison!C8 -> 0.075 | C2: =Comparison!D8 -> 0.079 | D2: =Comparison!E8 -> 0.085 | E2: =Comparison!F8 -> 0.066 | F2: =Comparison!G8 -> -0.166
A3: Marriott | B3: =Comparison!I8 -> 0.58084013 | C3: =Comparison!J8 -> 0.62285714 | D3: =Comparison!K8 -> 0.64861837 | E3: =Comparison!L8 -> 0.5147877 | F3: =Comparison!M8 -> 0.3666824
A4: M.O. | B4: =Comparison!O8 -> 0.16222898 | C4: =Comparison!P8 -> 0.18330048 | D4: =Comparison!Q8 -> 0.035674961 | E4: =Comparison!R8 -> -0.20384979 | F4: =Comparison!S8 -> -1.1976048
A5: NH | B5: =Comparison!U8 -> 0.16729393 | C5: =Comparison!V8 -> 0.15507179 | D5: =Comparison!W8 -> 0.14630748 | E5: =Comparison!X8 -> -0.11091762 | F5: =Comparison!Y8 -> -0.62085043
A17: Return on Sales | B17: 2024 | C17: 2023 | D17: 2022 | E17: 2021 | F17: 2020
A18: Industry | B18: =Comparison!C9 -> 0.139 | C18: =Comparison!D9 -> 0.148 | D18: =Comparison!E9 -> 0.161 | E18: =Comparison!F9 -> 0.126 | F18: =Comparison!G9 -> -0.115
A19: Marriott | B19: =Comparison!I9 -> 0.35886975 | C19: =Comparison!J9 -> 0.48936508 | D19: =Comparison!K9 -> 0.44025392 | E19: =Comparison!L9 -> 0.32181552 | F19: =Comparison!M9 -> -0.12600283
A20: M.O. | B20: =Comparison!O9 -> -0.17440091 | C20: =Comparison!P9 -> -0.65292958 | D20: =Comparison!Q9 -> -0.1294869 | E20: =Comparison!R9 -> -0.37267277 | F20: =Comparison!S9 -> -3.5351116
A21: NH | B21: =Comparison!U9 -> 0.089635634 | C21: =Comparison!V9 -> 0.061130153 | D21: =Comparison!W9 -> 0.059846726 | E21: =Comparison!X9 -> -0.18014735 | F21: =Comparison!Y9 -> -0.80727341
A33: Return on Total Assets | B33: 2024 | C33: 2023 | D33: 2022 | E33: 2021 | F33: 2020
A34: Industry | B34: =Comparison!C10 -> 0.041 | C34: =Comparison!D10 -> 0.038 | D34: =Comparison!E10 -> 0.031 | E34: =Comparison!F10 -> 0.018 | F34: =Comparison!G10 -> -0.045
A35: Marriott | B35: =Comparison!I10 -> 0.091599815 | C35: =Comparison!J10 -> 0.12212561 | D35: =Comparison!K10 -> 0.093630877 | E35: =Comparison!L10 -> 0.043737812 | F35: =Comparison!M10 -> -0.010733237
A36: M.O. | B36: =Comparison!O10 -> -0.021641349 | C36: =Comparison!P10 -> -0.091329682 | D36: =Comparison!Q10 -> -0.011373992 | E36: =Comparison!R10 -> -0.031456125 | F36: =Comparison!S10 -> -0.29728253
A37: NH | B37: =Comparison!U10 -> 0.049707506 | C37: =Comparison!V10 -> 0.031756 | D37: =Comparison!W10 -> 0.025096137 | E37: =Comparison!X10 -> -0.032228366 | F37: =Comparison!Y10 -> -0.10097066
A49: Return on Investment | B49: 2024 | C49: 2023 | D49: 2022 | E49: 2021 | F49: 2020
A50: Industry | B50: =Comparison!C11 -> 0.06453 | C50: =Comparison!D11 -> 0.06993 | D50: =Comparison!E11 -> 0.058829 | E50: =Comparison!F11 -> -0.00097 | F50: =Comparison!G11 -> -0.062442
A51: Marriott | B51: =Comparison!I11 -> 0.33557399 | C51: =Comparison!J11 -> 0.35063891 | D51: =Comparison!K11 -> 0.32674944 | E51: =Comparison!L11 -> 0.15218144 | F51: =Comparison!M11 -> 0.071904497
A52: M.O. | B52: =Comparison!O11 -> 0.026188941 | C52: =Comparison!P11 -> 0.0292503 | D52: =Comparison!Q11 -> 0.0040208488 | E52: =Comparison!R11 -> -0.015394514 | F52: =Comparison!S11 -> -0.050445988
A53: NH | B53: =Comparison!U11 -> 0.11033253 | C53: =Comparison!V11 -> 0.097003271 | D53: =Comparison!W11 -> 0.074168038 | E53: =Comparison!X11 -> -0.023526136 | F53: =Comparison!Y11 -> -0.086321347
A65: Return on Equity | B65: 2024 | C65: 2023 | D65: 2022 | E65: 2021 | F65: 2020
A66: Industry | B66: =Comparison!C12 -> 0.115 | C66: =Comparison!D12 -> 0.097 | D66: =Comparison!E12 -> 0.065 | E66: =Comparison!F12 -> -0.021 | F66: =Comparison!G12 -> -0.246
A67: Marriott | B67: =Comparison!I12 -> -1.2928688 | C67: =Comparison!J12 -> -54.087719 | D67: =Comparison!K12 -> 2.3794147 | E67: =Comparison!L12 -> 1.191974 | F67: =Comparison!M12 -> -0.47131509
A68: M.O. | B68: =Comparison!O12 -> -0.027085632 | C68: =Comparison!P12 -> -0.11668719 | D68: =Comparison!Q12 -> -0.015038847 | E68: =Comparison!R12 -> -0.041579279 | F68: =Comparison!S12 -> -0.17849
A69: NH | B69: =Comparison!U12 -> 0.2013537 | C69: =Comparison!V12 -> 0.14043794 | D69: =Comparison!W12 -> 0.12378167 | E69: =Comparison!X12 -> -0.18820765 | F69: =Comparison!Y12 -> -0.44509667
A81: Sales Growth Ratio | B81: 2024 | C81: 2023 | D81: 2022 | E81: 2021 | F81: 2020
A82: Industry | B82: =Comparison!C13 -> 0.07023 | C82: =Comparison!D13 -> 0.08233 | D82: =Comparison!E13 -> 0.6979 | E82: =Comparison!F13 -> 0.7839 | F82: =Comparison!G13 -> -0.7038
A83: Marriott | B83: =Comparison!I13 -> 0.05047619 | C83: =Comparison!J13 -> 0.17625093 | D83: =Comparison!K13 -> 0.56837482 | E83: =Comparison!L13 -> 0.61160925 | F83: =Comparison!M13 -> -0.6056207
A84: M.O. | B84: =Comparison!O13 -> -0.057874933 | C84: =Comparison!P13 -> 0.22902444 | D84: =Comparison!Q13 -> 0.43294415 | E84: =Comparison!R13 -> 0.72509526 | F84: =Comparison!S13 -> -0.89245234
A85: NH | B85: =Comparison!U13 -> 0.11991663 | C85: =Comparison!V13 -> 0.25348351 | D85: =Comparison!W13 -> 1.3073007 | E85: =Comparison!X13 -> 0.3922044 | F85: =Comparison!Y13 -> -0.68608028

Sheet Debt Graphs
A1: Debt to Asset Ratio | B1: 2024 | C1: 2023 | D1: 2022 | E1: 2021 | F1: 2020
A2: Industry | B2: =Comparison!C16 -> 0.79 | C2: =Comparison!D16 -> 0.81 | D2: =Comparison!E16 -> 0.83 | E2: =Comparison!F16 -> 0.76 | F2: =Comparison!G16 -> 0.81
A3: Marriott | B3: =Comparison!I16 -> 0.55179131 | C3: =Comparison!J16 -> 0.46245229 | D3: =Comparison!K16 -> 0.40556115 | E3: =Comparison!L16 -> 0.39674402 | F3: =Comparison!M16 -> 0.42006396
A4: M.O. | B4: =Comparison!O16 -> 0.11685246 | C4: =Comparison!P16 -> 0.14204075 | D4: =Comparison!Q16 -> 0.17198486 | E4: =Comparison!R16 -> 0.20017209 | F4: =Comparison!S16 -> 0.1853698
A5: NH | B5: =Comparison!U16 -> 0.54104792 | C5: =Comparison!V16 -> 0.58101298 | D5: =Comparison!W16 -> 0.60762093 | E5: =Comparison!X16 -> 0.66703367 | F5: =Comparison!Y16 -> 0.70622878
A17: Debt to Equity Ratio | B17: 2024 | C17: 2023 | D17: 2022 | E17: 2021 | F17: 2020
A18: Industry | B18: =Comparison!C17 -> 3.22 | C18: =Comparison!D17 -> 3.11 | D18: =Comparison!E17 -> 2.78 | E18: =Comparison!F17 -> 2.71 | F18: =Comparison!G17 -> 2.6
A19: Marriott | B19: =Comparison!I17 -> 4.8285428 | C19: =Comparison!J17 -> 17.409091 | D19: =Comparison!K17 -> 17.71831 | E19: =Comparison!L17 -> 7.1697313 | F19: =Comparison!M17 -> 24.130233
A20: M.O. | B20: =Comparison!O17 -> 0.14436793 | C20: =Comparison!P17 -> 0.17936267 | D20: =Comparison!Q17 -> 0.22179767 | E20: =Comparison!R17 -> 0.26688404 | F20: =Comparison!S17 -> 0.24134692
A21: NH | B21: =Comparison!U17 -> 2.0646332 | C21: =Comparison!V17 -> 2.4185098 | D21: =Comparison!W17 -> 2.772319 | E21: =Comparison!X17 -> 3.50587 | F21: =Comparison!Y17 -> 3.82898
A33: Total debt to Capitalization Ratio | B33: 2024 | C33: 2023 | D33: 2022 | E33: 2021 | F33: 2020
A34: Industry | B34: =Comparison!C18 -> 0.4346 | C34: =Comparison!D18 -> 0.388 | D34: =Comparison!E18 -> 0.3856 | E34: =Comparison!F18 -> 0.4314 | F34: =Comparison!G18 -> 0.4669
A35: Marriott | B35: =Comparison!I18 -> 1.261196 | C35: =Comparison!J18 -> 1.0609418 | D35: =Comparison!K18 -> 0.94657637 | E35: =Comparison!L18 -> 0.87759695 | F35: =Comparison!M18 -> 0.96020729
A36: M.O. | B36: =Comparison!O18 -> 0.12615517 | C36: =Comparison!P18 -> 0.15208441 | D36: =Comparison!Q18 -> 0.18153388 | E36: =Comparison!R18 -> 0.21066177 | F36: =Comparison!S18 -> 0.19442343
A37: NH | B37: =Comparison!U18 -> 0.67369667 | C37: =Comparison!V18 -> 0.70747487 | D37: =Comparison!W18 -> 0.73491107 | E37: =Comparison!X18 -> 0.77806728 | F37: =Comparison!Y18 -> 0.79291693
A49: Interest Coverage Ratio | B49: 2024 | C49: 2023 | D49: 2022 | E49: 2021 | F49: 2020
A50: Industry | B50: =Comparison!C19 -> 3.95 | C50: =Comparison!D19 -> 3.35 | D50: =Comparison!E19 -> 2.52 | E50: =Comparison!F19 -> 1.8 | F50: =Comparison!G19 -> -2.34
A51: Marriott | B51: =Comparison!I19 -> 5.5309353 | C51: =Comparison!J19 -> 6.9451327 | D51: =Comparison!K19 -> 8.6203474 | E51: =Comparison!L19 -> 4.1857143 | F51: =Comparison!M19 -> 1.7460674
A52: M.O. | B52: =Comparison!O19 -> 8.4455446 | C52: =Comparison!P19 -> 6.0176471 | D52: =Comparison!Q19 -> 1.0657895 | E52: =Comparison!R19 -> -5.3833333 | F52: =Comparison!S19 -> -16.793893
A53: NH | B53: =Comparison!U19 -> 3.4425532 | C53: =Comparison!V19 -> 2.90625 | D53: =Comparison!W19 -> 2.1575342 | E53: =Comparison!X19 -> -0.67536705 | F53: =Comparison!Y19 -> -2.7264537

Sheet Profitability Graphs
A1: Fixed Asset Turnover Ratio | B1: 2024 | C1: 2023 | D1: 2022 | E1: 2021 | F1: 2020
A2: Industry | B2: =Comparison!C22 -> 0.4356 | C2: =Comparison!D22 -> 0.4338 | D2: =Comparison!E22 -> 0.3999 | E2: =Comparison!F22 -> 0.234 | F2: =Comparison!G22 -> 0.1257
A3: Marriott | B3: =Comparison!I22 -> 0.29374168 | C3: =Comparison!J22 -> 0.28724496 | D3: =Comparison!K22 -> 0.24665546 | E3: =Comparison!L22 -> 0.15592539 | F3: =Comparison!M22 -> 0.096757991
A4: M.O. | B4: =Comparison!O22 -> 0.16622145 | C4: =Comparison!P22 -> 0.15785157 | D4: =Comparison!Q22 -> 0.11279045 | E4: =Comparison!R22 -> 0.074947378 | F4: =Comparison!S22 -> 0.040545611
A5: NH | B5: =Comparison!U22 -> 0.40890254 | C5: =Comparison!V22 -> 0.38849591 | D5: =Comparison!W22 -> 0.31530744 | E5: =Comparison!X22 -> 0.13213652 | F5: =Comparison!Y22 -> 0.09196112

Sheet Operating Graphs
A1: Days' Inventory on Hand Ratio | B1: 2024 | C1: 2023 | D1: 2022 | E1: 2021 | F1: 2020
A2: Industry | B2: =Comparison!C25 -> 7 | C2: =Comparison!D25 -> 6 | D2: =Comparison!E25 -> 8 | E2: =Comparison!F25 -> 9 | F2: =Comparison!G25 -> 13
A3: Marriott | B3: =Comparison!I25 | C3: =Comparison!J25 | D3: =Comparison!K25 | E3: =Comparison!L25 | F3: =Comparison!M25
A4: M.O. | B4: =Comparison!O25 -> 6.6144578 | C4: =Comparison!P25 -> 5.9280855 | D4: =Comparison!Q25 -> 6.2269574 | E4: =Comparison!R25 -> 7.9138921 | F4: =Comparison!S25 -> 13.448536 | G4: =Comparison!T25
A5: NH | B5: =Comparison!U25 | C5: =Comparison!V25 | D5: =Comparison!W25 | E5: =Comparison!X25 | F5: =Comparison!Y25
A17: Accounts Receivable Turnover Ratio | B17: 2024 | C17: 2023 | D17: 2022 | E17: 2021 | F17: 2020
A18: Industry | B18: =Comparison!C26 -> 72.32 | C18: =Comparison!D26 -> 67.57 | D18: =Comparison!E26 -> 62.43 | E18: =Comparison!F26 -> 36.77 | F18: =Comparison!G26 -> 20.61
A19: Marriott | B19: =Comparison!I26 -> 2.4034865 | C19: =Comparison!J26 -> 2.3850085 | D19: =Comparison!K26 -> 2.3527345 | E19: =Comparison!L26 -> 1.8213333 | F19: =Comparison!M26 -> 1.0180159
A20: M.O. | B20: =Comparison!O26 -> 7.1634877 | C20: =Comparison!P26 -> 9.1868313 | D20: =Comparison!Q26 -> 8.6992337 | E20: =Comparison!R26 -> 7.9623116 | F20: =Comparison!S26 -> 3.8796199
A21: NH | B21: =Comparison!U26 -> 11.555078 | C21: =Comparison!V26 -> 11.15186 | D21: =Comparison!W26 -> 10.995212 | E21: =Comparison!X26 -> 6.2810265 | F21: =Comparison!Y26 -> 10.575937
A33: Accounts Receivable Days on Hand | B33: 2024 | C33: 2023 | D33: 2022 | E33: 2021 | F33: 2020
A34: Industry | B34: =Comparison!C27 -> 22 | C34: =Comparison!D27 -> 19 | D34: =Comparison!E27 -> 23 | E34: =Comparison!F27 -> 19 | F34: =Comparison!G27 -> 48
A35: Marriott | B35: =Comparison!I27 -> 152.27879 | C35: =Comparison!J27 -> 153.45857 | D35: =Comparison!K27 -> 155.56367 | E35: =Comparison!L27 -> 200.95168 | F35: =Comparison!M27 -> 359.52289
A36: M.O. | B36: =Comparison!O27 -> 51.092431 | C36: =Comparison!P27 -> 39.839634 | D36: =Comparison!Q27 -> 42.072671 | E36: =Comparison!R27 -> 45.966551 | F36: =Comparison!S27 -> 94.33914
A37: NH | B37: =Comparison!U27 -> 31.674387 | C37: =Comparison!V27 -> 32.819639 | D37: =Comparison!W27 -> 33.287216 | E37: =Comparison!X27 -> 58.27073 | F37: =Comparison!Y27 -> 34.606863
A49: Accounts Payable Turnover Ratio | B49: 2024 | C49: 2023 | D49: 2022 | E49: 2021 | F49: 2020
A50: Industry | B50: =Comparison!C28 -> 10.63 | C50: =Comparison!D28 -> 9.5923 | D50: =Comparison!E28 -> 21.47 | E50: =Comparison!F28 -> 37.0513 | F50: =Comparison!G28 -> 9.706
A51: Marriott | B51: =Comparison!I28 -> 1.8427715 | C51: =Comparison!J28 -> 1.8247978 | D51: =Comparison!K28 -> 1.7214674 | E51: =Comparison!L28 -> 1.5227454 | F51: =Comparison!M28 -> 1.4546913
A52: M.O. | B52: =Comparison!O28 -> 1.62886 | C52: =Comparison!P28 -> 1.9470199 | D52: =Comparison!Q28 -> 3.4417283 | E52: =Comparison!R28 -> 16.433962 | F52: =Comparison!S28 -> 12.73224
A53: NH | B53: =Comparison!U28 -> 2.3134526 | C53: =Comparison!V28 -> 2.2689527 | D53: =Comparison!W28 -> 2.2985302 | E53: =Comparison!X28 -> 1.5804496 | F53: =Comparison!Y28 -> 1.5533189
A65: Accounts Payable Days on Hand | B65: 2024 | C65: 2023 | D65: 2022 | E65: 2021 | F65: 2020
A66: Industry | B66: =Comparison!C29 -> 34.43 | C66: =Comparison!D29 -> 38.06 | D66: =Comparison!E29 -> 17.0004 | E66: =Comparison!F29 -> 9.8512 | F66: =Comparison!G29 -> 37.7086
A67: Marriott | B67: =Comparison!I29 -> 198.61388 | C67: =Comparison!J29 -> 200.57016 | D67: =Comparison!K29 -> 212.60931 | E67: =Comparison!L29 -> 240.35535 | F67: =Comparison!M29 -> 251.59978
A68: M.O. | B68: =Comparison!O29 -> 224.69702 | C68: =Comparison!P29 -> 187.97959 | D68: =Comparison!Q29 -> 106.34192 | E68: =Comparison!R29 -> 22.270953 | F68: =Comparison!S29 -> 28.745923
A69: NH | B69: =Comparison!U29 -> 158.2051 | C69: =Comparison!V29 -> 161.3079 | D69: =Comparison!W29 -> 159.23219 | E69: =Comparison!X29 -> 231.57967 | F69: =Comparison!Y29 -> 235.6245
A81: Operating Expense Ratio | B81: 2024 | C81: 2023 | D81: 2022 | E81: 2021 | F81: 2020
A82: Industry | B82: =Comparison!C30 -> 0.2635 | C82: =Comparison!D30 -> 0.2713 | D82: =Comparison!E30 -> 0.2886 | E82: =Comparison!F30 -> 0.101 | F82: =Comparison!G30 -> -0.1895
A83: Marriott | B83: =Comparison!I30 | C83: =Comparison!J30 | D83: =Comparison!K30 | E83: =Comparison!L30 | F83: =Comparison!M30
A84: M.O. | B84: =Comparison!O30 | C84: =Comparison!P30 | D84: =Comparison!Q30 | E84: =Comparison!R30 | F84: =Comparison!S30
A85: NH | B85: =Comparison!U30 | C85: =Comparison!V30 | D85: =Comparison!W30 | E85: =Comparison!X30 | F85: =Comparison!Y30
A96: Total Asset Turnover Ratio | B96: 2024 | C96: 2023 | D96: 2022 | E96: 2021 | F96: 2020
A97: Industry | B97: =Comparison!C31 -> 0.4356 | C97: =Comparison!D31 -> 0.4338 | D97: =Comparison!E31 -> 0.3999 | E97: =Comparison!F31 -> 0.234 | F97: =Comparison!G31 -> 0.1257
A98: Marriott | B98: =Comparison!I31 -> 0.25524529 | C98: =Comparison!J31 -> 0.24955931 | D98: =Comparison!K31 -> 0.21267471 | E98: =Comparison!L31 -> 0.13590958 | F98: =Comparison!M31 -> 0.085182505
A99: M.O. | B99: =Comparison!O31 -> 0.14482654 | C99: =Comparison!P31 -> 0.13957036 | D99: =Comparison!Q31 -> 0.10476531 | E99: =Comparison!R31 -> 0.070498204 | F99: =Comparison!S31 -> 0.03794357
A100: NH | B100: =Comparison!U31 -> 0.5515571 | C100: =Comparison!V31 -> 0.51949452 | D100: =Comparison!W31 -> 0.41934989 | E100: =Comparison!X31 -> 0.17699577 | F100: =Comparison!Y31 -> 0.12295607
